Workbook

Sheet Спр отношение элементов в сезон
A1: id | B1: nm_season | C1: element_season | D1: nm_elementa_season | E1: coef_element_in_season | F1: key_element_connect | G1: id_element_st | H1: id_element_en | I1: nm_elemet_st | J1: nm_element_en | K1: id_connect | L1: nm_connect | M1: coef_connect | N1: coef_st_elemnt_in_season | O1: total_coef_in_season | P1: key_season_el_st_el_en
A2: 1 | B2: Начало весны | C2: 1 | D2: Дерево | E2: 1 | F2: 1_1 | G2: 1 | H2: 1 | I2: Дерево | J2: Дерево | K2: 5 | L2: Партнерство | M2: 1 | N2: 1 | O2: 1 | P2: 1_1_1
A3: 1 | B3: Начало весны | C3: 1 | D3: Дерево | E3: 1 | F3: 1_2 | G3: 1 | H3: 2 | I3: Дерево | J3: Огонь | K3: 3 | L3: Ослабление | M3: 0.5 | N3: 1 | O3: 0.5 | P3: 1_1_2
A4: 1 | B4: Начало весны | C4: 1 | D4: Дерево | E4: 1 | F4: 1_3 | G4: 1 | H4: 3 | I4: Дерево | J4: Земля | K4: 4 | L4: Истощение | M4: 0 | N4: 1 | O4: 0 | P4: 1_1_3
A5: 1 | B5: Начало весны | C5: 1 | D5: Дерево | E5: 1 | F5: 1_4 | G5: 1 | H5: 4 | I5: Дерево | J5: Металл | K5: 2 | L5: Контроль | M5: 0.9 | N5: 1 | O5: 0.9 | P5: 1_1_4
A6: 1 | B6: Начало весны | C6: 1 | D6: Дерево | E6: 1 | F6: 1_5 | G6: 1 | H6: 5 | I6: Дерево | J6: Вода | K6: 1 | L6: Усиление | M6: 1.15 | N6: 1 | O6: 1.15 | P6: 1_1_5
A7: 1 | B7: Начало весны | C7: 1 | D7: Дерево | E7: 1 | F7: 2_1 | G7: 2 | H7: 1 | I7: Огонь | J7: Дерево | K7: 1 | L7: Усиление | M7: 1.15 | N7: 1.15 | O7: 1.3225 | P7: 1_2_1
A8: 1 | B8: Начало весны | C8: 1 | D8: Дерево | E8: 1 | F8: 2_2 | G8: 2 | H8: 2 | I8: Огонь | J8: Огонь | K8: 5 | L8: Партнерство | M8: 1 | N8: 1.15 | O8: 1.15 | P8: 1_2_2
A9: 1 | B9: Начало весны | C9: 1 | D9: Дерево | E9: 1 | F9: 2_3 | G9: 2 | H9: 3 | I9: Огонь | J9: Земля | K9: 3 | L9: Ослабление | M9: 0.5 | N9: 1.15 | O9: 0.575 | P9: 1_2_3
A10: 1 | B10: Начало весны | C10: 1 | D10: Дерево | E10: 1 | F10: 2_4 | G10: 2 | H10: 4 | I10: Огонь | J10: Металл | K10: 4 | L10: Истощение | M10: 0 | N10: 1.15 | O10: 0 | P10: 1_2_4
A11: 1 | B11: Начало весны | C11: 1 | D11: Дерево | E11: 1 | F11: 2_5 | G11: 2 | H11: 5 | I11: Огонь | J11: Вода | K11: 2 | L11: Контроль | M11: 0.9 | N11: 1.15 | O11: 1.035 | P11: 1_2_5
A12: 1 | B12: Начало весны | C12: 1 | D12: Дерево | E12: 1 | F12: 3_1 | G12: 3 | H12: 1 | I12: Земля | J12: Дерево | K12: 2 | L12: Контроль | M12: 0.9 | N12: 0.9 | O12: 0.81 | P12: 1_3_1
A13: 1 | B13: Начало весны | C13: 1 | D13: Дерево | E13: 1 | F13: 3_2 | G13: 3 | H13: 2 | I13: Земля | J13: Огонь | K13: 1 | L13: Усиление | M13: 1.15 | N13: 0.9 | O13: 1.035 | P13: 1_3_2
... A601: 24 | B601: Большие холода | C601: 3 | D601: Земля | E601: 1 | F601: 5_5 | G601: 5 | H601: 5 | I601: Вода | J601: Вода | K601: 5 | L601: Партнерство | M601: 1 | N601: 0.9 | O601: 0.9 | P601: 24_5_5

Sheet Спр 5 элементов
A1: id_element | B1: nm_elementa_rus | C1: nm_element_cha
A2: 1 | B2: Дерево | C2: 木
A3: 2 | B3: Огонь | C3: 火
A4: 3 | B4: Земля | C4: 土
A5: 4 | B5: Металл | C5: 金
A6: 5 | B6: Вода | C6: 水

Sheet Спр 10 НС
A1: id | B1: hieroglyph_cha | C1: yin_yan | D1: element | E1: orientation | F1: nm_rus
A2: 1 | B2: 甲 | C2: 1 | D2: 1 | E2: 1 | F2: Цзя
A3: 2 | B3: 乙 | C3: 2 | D3: 1 | E3: 1 | F3: И
A4: 3 | B4: 丙 | C4: 1 | D4: 2 | E4: 3 | F4: Бин
A5: 4 | B5: 丁 | C5: 2 | D5: 2 | E5: 3 | F5: Дин
A6: 5 | B6: 戊 | C6: 1 | D6: 3 | E6: 0 | F6: У
A7: 6 | B7: 己 | C7: 2 | D7: 3 | E7: 0 | F7: Цзи
A8: 7 | B8: 庚 | C8: 1 | D8: 4 | E8: 5 | F8: Гэн
A9: 8 | B9: 辛 | C9: 2 | D9: 4 | E9: 5 | F9: Синь
A10: 9 | B10: 壬 | C10: 1 | D10: 5 | E10: 7 | F10: Жэнь
A11: 10 | B11: 癸 | C11: 2 | D11: 5 | E11: 7 | F11: Гуй

Sheet Спр 12 Земных ветвей
A1: id_animal | B1: nm_animal_rus | C1: hieroglyph_cha | D1: nm_animal_cha | E1: yin_yan | F1: element | G1: orientation | H1: month_grigorian | I1: coef_element_month
A2: 1 | B2: Тигр | C2: 寅 | D2: Инь | E2: 1 | F2: 1 | G2: 1 | H2: 2 | I2: 1
A3: 2 | B3: Кролик | C3: 卯 | D3: Мао | E3: 2 | F3: 1 | G3: 1 | H3: 3 | I3: 1.15
A4: 3 | B4: Дракон | C4: 辰 | D4: Чэнь | E4: 1 | F4: 3 | G4: 0 | H4: 4 | I4: 1
A5: 4 | B5: Змея | C5: 巳 | D5: Сы | E5: 2 | F5: 2 | G5: 3 | H5: 5 | I5: 1
A6: 5 | B6: Лошадь | C6: 午 | D6: У | E6: 1 | F6: 2 | G6: 3 | H6: 6 | I6: 1.15
A7: 6 | B7: Коза | C7: 未 | D7: Вэй | E7: 2 | F7: 3 | G7: 0 | H7: 7 | I7: 1
A8: 7 | B8: Обезьяна | C8: 申 | D8: Шэнь | E8: 1 | F8: 4 | G8: 5 | H8: 8 | I8: 1
A9: 8 | B9: Петух | C9: 酉 | D9: Ю | E9: 2 | F9: 4 | G9: 5 | H9: 9 | I9: 1.15
A10: 9 | B10: Собака | C10: 戌 | D10: Сюй | E10: 1 | F10: 3 | G10: 0 | H10: 10 | I10: 1
A11: 10 | B11: Свинья | C11: 亥 | D11: Хай | E11: 2 | F11: 5 | G11: 7 | H11: 11 | I11: 1
A12: 11 | B12: Крыса | C12: 子 | D12: Цзы | E12: 1 | F12: 5 | G12: 7 | H12: 12 | I12: 1.15
A13: 12 | B13: Бык | C13: 丑 | D13: Чоу | E13: 2 | F13: 3 | G13: 0 | H13: 1 | I13: 1

Sheet Спр круга Усин
A1: id_element_st | B1: id_element_en | C1: id_connect | D1: nm_elemet_st | E1: nm_element_en | F1: nm_connect | G1: key_element_connect | H1: coef_connect
A2: 1 | B2: 1 | C2: 5 | D2: Дерево | E2: Дерево | F2: Партнерство | G2: 1_1 | H2: 1
A3: 1 | B3: 2 | C3: 3 | D3: Дерево | E3: Огонь | F3: Ослабление | G3: 1_2 | H3: 0.5
A4: 1 | B4: 3 | C4: 4 | D4: Дерево | E4: Земля | F4: Истощение | G4: 1_3 | H4: 0
A5: 1 | B5: 4 | C5: 2 | D5: Дерево | E5: Металл | F5: Контроль | G5: 1_4 | H5: 0.9
A6: 1 | B6: 5 | C6: 1 | D6: Дерево | E6: Вода | F6: Усиление | G6: 1_5 | H6: 1.15
A7: 2 | B7: 1 | C7: 1 | D7: Огонь | E7: Дерево | F7: Усиление | G7: 2_1 | H7: 1.15
A8: 2 | B8: 2 | C8: 5 | D8: Огонь | E8: Огонь | F8: Партнерство | G8: 2_2 | H8: 1
A9: 2 | B9: 3 | C9: 3 | D9: Огонь | E9: Земля | F9: Ослабление | G9: 2_3 | H9: 0.5
A10: 2 | B10: 4 | C10: 4 | D10: Огонь | E10: Металл | F10: Истощение | G10: 2_4 | H10: 0
A11: 2 | B11: 5 | C11: 2 | D11: Огонь | E11: Вода | F11: Контроль | G11: 2_5 | H11: 0.9
A12: 3 | B12: 1 | C12: 2 | D12: Земля | E12: Дерево | F12: Контроль | G12: 3_1 | H12: 0.9
A13: 3 | B13: 2 | C13: 1 | D13: Земля | E13: Огонь | F13: Усиление | G13: 3_2 | H13: 1.15
... A26: 5 | B26: 5 | C26: 5 | D26: Вода | E26: Вода | F26: Партнерство | G26: 5_5 | H26: 1

Sheet Спр дворцов
A1: id | B1: nm_cha | C1: nm_rus | D1: id_element | E1: num | F1: direction | G1: id_scdg | K1: Дворец | L1: Животное | M1: Знак животного | N1: Какая полярность года | O1: Направление дворца | P1: Направление животного | Q1: Удачные для меня градусы
A2: 1 | B2: 坎 | C2: Кань | D2: 5 | E2: 1 | F2: Север | K2: 4 | L2: Дракон | M2: 辰 | N2: Инь | O2: =VLOOKUP(K2,Спр_дворцов[[num]:[direction]],2,FALSE) -> Юго-Восток | P2: ЮВ-1 | Q2: 123,75-127,5 | R2: =_xlfn.CONCAT(P2," (",Q2,")") -> ЮВ-1 (123,75-127,5)
A3: 8 | C3: Гэнь | D3: 3 | E3: 8 | F3: Северо-восток | K3: 4 | L3: Змея | M3: 巳 | N3: Ян | O3: =VLOOKUP(K3,Спр_дворцов[[num]:[direction]],2,FALSE) -> Юго-Восток | P3: ЮВ-3 | Q3: 142,5-146,25 | R3: =_xlfn.CONCAT(P3," (",Q3,")") -> ЮВ-3 (142,5-146,25)
A4: 3 | B4: 震 | C4: Чжэнь | D4: 1 | E4: 3 | F4: Восток | K4: 9 | L4: Лошадь | M4: 午 | N4: Инь | O4: =VLOOKUP(K4,Спр_дворцов[[num]:[direction]],2,FALSE) -> Юг | P4: Ю-2 | Q4: 172,5-187,5 | R4: =_xlfn.CONCAT(P4," (",Q4,")") -> Ю-2 (172,5-187,5)
A5: 4 | B5: 巽 | C5: Сюнь | D5: 1 | E5: 4 | F5: Юго-Восток | K5: 2 | L5: Коза | M5: 未 | N5: Ян | O5: =VLOOKUP(K5,Спр_дворцов[[num]:[direction]],2,FALSE) -> Юго-Запад | P5: ЮЗ-1 | Q5: 213,75-217,5 | R5: =_xlfn.CONCAT(P5," (",Q5,")") -> ЮЗ-1 (213,75-217,5)
A6: 9 | B6: 离 | C6: Ли | D6: 2 | E6: 9 | F6: Юг | K6: 2 | L6: Обезьяна | M6: 申 | N6: Инь | O6: =VLOOKUP(K6,Спр_дворцов[[num]:[direction]],2,FALSE) -> Юго-Запад | P6: ЮЗ-3 | Q6: 232,5-236,25 | R6: =_xlfn.CONCAT(P6," (",Q6,")") -> ЮЗ-3 (232,5-236,25)
A7: 2 | B7: 坤 | C7: Кунь | D7: 3 | E7: 2 | F7: Юго-Запад | K7: 7 | L7: Петух | M7: 酉 | N7: Ян | O7: =VLOOKUP(K7,Спр_дворцов[[num]:[direction]],2,FALSE) -> Запад | P7: З-2 | Q7: 262,5-277,5 | R7: =_xlfn.CONCAT(P7," (",Q7,")") -> З-2 (262,5-277,5)
A8: 7 | B8: 兑 | C8: Дуй | D8: 4 | E8: 7 | F8: Запад | K8: 6 | L8: Собака | M8: 戌 | N8: Инь | O8: =VLOOKUP(K8,Спр_дворцов[[num]:[direction]],2,FALSE) -> Северо-Запад | P8: СЗ-1 | Q8: 303,75-307,5 | R8: =_xlfn.CONCAT(P8," (",Q8,")") -> СЗ-1 (303,75-307,5)
A9: 6 | B9: 乾 | C9: Цянь | D9: 4 | E9: 6 | F9: Северо-Запад | K9: 6 | L9: Свинья | M9: 亥 | N9: Ян | O9: =VLOOKUP(K9,Спр_дворцов[[num]:[direction]],2,FALSE) -> Северо-Запад | P9: СЗ-3 | Q9: 322,5-326,25 | R9: =_xlfn.CONCAT(P9," (",Q9,")") -> СЗ-3 (322,5-326,25)
K10: 1 | L10: Крыса | M10: 子 | N10: Инь | O10: =VLOOKUP(K10,Спр_дворцов[[num]:[direction]],2,FALSE) -> Север | P10: С-2 | Q10: 352,5-7,5 | R10: =_xlfn.CONCAT(P10," (",Q10,")") -> С-2 (352,5-7,5)
K11: 8 | L11: Бык | M11: 丑 | N11: Ян | O11: =VLOOKUP(K11,Спр_дворцов[[num]:[direction]],2,FALSE) -> Северо-восток | P11: СВ-1 | Q11: 33,75-37,5 | R11: =_xlfn.CONCAT(P11," (",Q11,")") -> СВ-1 (33,75-37,5)
K12: 8 | L12: Тигр | M12: 寅 | N12: Инь | O12: =VLOOKUP(K12,Спр_дворцов[[num]:[direction]],2,FALSE) -> Северо-восток | P12: СВ-3 | Q12: 52,5-56,25 | R12: =_xlfn.CONCAT(P12," (",Q12,")") -> СВ-3 (52,5-56,25)
K13: 3 | L13: Кролик | M13: 卯 | N13: Ян | O13: =VLOOKUP(K13,Спр_дворцов[[num]:[direction]],2,FALSE) -> Восток | P13: В-2 | Q13: 82,5-97,5 | R13: =_xlfn.CONCAT(P13," (",Q13,")") -> В-2 (82,5-97,5)

Sheet Спр звезд
A1: id | B1: star_cha | C1: star_rus_1 | D1: star_rus_2 | E1: id_element | F1: id_palace | G1: koef
A2: 1 | B2: 蓬 | C2: Тянь Пэн | D2: Разбойник на воде | E2: 5 | F2: 1 | G2: -1
A3: 2 | B3: 任 | C3: Тянь Жэнь | D3: Небесный Чиновник | E3: 3 | F3: 8 | G3: 1
A4: 3 | B4: 冲 | C4: Тянь Чун | D4: Небесный Пробой | E4: 1 | F4: 3 | G4: -1
A5: 4 | B5: 辅 | C5: Тянь Фу | D5: Небесная Помощь | E5: 1 | F5: 4 | G5: 1
A6: 5 | B6: 英 | C6: Тянь Ин | D6: Небесный блеск | E6: 2 | F6: 9 | G6: -1
A7: 6 | B7: 芮 | C7: Тянь Жуй | D7: Небесный росток | E7: 3 | F7: 2 | G7: -1
A8: 7 | B8: 禽 | C8: Тянь Цинь | D8: Дикая Птица | E8: 3 | F8: 5 | G8: 1
A9: 8 | B9: 柱 | C9: Тянь Чжу | D9: Разбитая армия | E9: 4 | F9: 7 | G9: -1
A10: 9 | B10: 心 | C10: Тянь Синь | D10: Небесное сердце | E10: 4 | F10: 6 | G10: -1

Sheet Спр духов
A1: id | B1: spirit_cha | C1: spirit_rus_1 | D1: spirit_rus_2 | E1: id_element | F1: id_palace | G1: koef
A2: 1 | B2: 符 | C2: Чжи Фу | D2: Главный дух | E2: 3 | G2: 1.15
A3: 2 | B3: 蛇 | C3: Тэн Шэ | D3: Дух Пернатого Змея | E3: 2 | G3: -1
A4: 3 | B4: 陰 | C4: Тай Инь | D4: Дух Великого Инь | E4: 4 | G4: 1
A5: 4 | B5: 合 | C5: Лю Хэ | D5: Дух Шести соединений | E5: 1 | G5: 1
A6: 5 | B6: 虎 | C6: Бай Ху | D6: Дух Белого Тигра | E6: 4 | G6: -1
A7: 6 | B7: 武 | C7: Сюань У | D7: Дух Темного воина | E7: 5 | G7: -1
A8: 7 | B8: 地 | C8: Дзю Ди | D8: Дух Девяти Земель | E8: 3 | G8: 1
A9: 8 | B9: 天 | C9: Дзю Тянь | D9: Дух Девяти Небес | E9: 4 | G9: 1

Sheet Спр Фаза Ци
A1: id | B1: sky | C1: earth | D1: jazi | E1: id_faza | F1: nm_faza_ci | G1: koef_ci
A2: 1 | B2: 甲 | C2: 亥 | D2: 甲亥 | E2: 1 | F2: Рост и развитие (Рождение) | G2: 1.15
A3: 2 | B3: 甲 | C3: 子 | D3: 甲子 | E3: 2 | F3: Ванная (Купание) | G3: 0
A4: 3 | B4: 甲 | C4: 丑 | D4: 甲丑 | E4: 3 | F4: Шапка и поясн (Надевание шапки, опоясывание, школа) | G4: 1
A5: 4 | B5: 甲 | C5: 寅 | D5: 甲寅 | E5: 4 | F5: Формирование дуачи (Поступление на службу, жалование) | G5: 1
A6: 5 | B6: 甲 | C6: 卯 | D6: 甲卯 | E6: 5 | F6: Императорский светильник (Расцвет) | G6: 1.15
A7: 7 | B7: 甲 | C7: 辰 | D7: 甲辰 | E7: 6 | F7: Ослабление (Пенсия) | G7: 0.5
A8: 8 | B8: 甲 | C8: 巳 | D8: 甲巳 | E8: 7 | F8: Болезнь | G8: 0.5
A9: 9 | B9: 甲 | C9: 午 | D9: 甲午 | E9: 8 | F9: Смерть | G9: 0.15
A10: 10 | B10: 甲 | C10: 未 | D10: 甲未 | E10: 9 | F10: Могила | G10: 0
A11: 11 | B11: 甲 | C11: 申 | D11: 甲申 | E11: 10 | F11: Разложение (Исчезновение, обрыв) | G11: 0
A12: 12 | B12: 甲 | C12: 酉 | D12: 甲酉 | E12: 11 | F12: Эмбрион (Зачатие) | G12: 0.5
A13: 13 | B13: 甲 | C13: 戌 | D13: 甲戌 | E13: 12 | F13: Питание (Вынашивание, зародыш) | G13: 0.5
... A121: 121 | B121: 癸 | C121: 辰 | D121: 癸辰 | E121: 12 | F121: Питание (Вынашивание, зародыш) | G121: 0.5

Sheet Спр НС
A1: id | B1: hieroglyph_cha | C1: yin_yan | D1: element | E1: orientation | F1: nm_rus
A2: 1 | B2: 甲 | C2: 1 | D2: 1 | E2: 1 | F2: Цзя
A3: 2 | B3: 乙 | C3: 2 | D3: 1 | E3: 1 | F3: И
A4: 3 | B4: 丙 | C4: 1 | D4: 2 | E4: 3 | F4: Бин
A5: 4 | B5: 丁 | C5: 2 | D5: 2 | E5: 3 | F5: Дин
A6: 5 | B6: 戊 | C6: 1 | D6: 3 | E6: 0 | F6: У
A7: 6 | B7: 己 | C7: 2 | D7: 3 | E7: 0 | F7: Цзи
A8: 7 | B8: 庚 | C8: 1 | D8: 4 | E8: 5 | F8: Гэн
A9: 8 | B9: 辛 | C9: 2 | D9: 4 | E9: 5 | F9: Синь
A10: 9 | B10: 壬 | C10: 1 | D10: 5 | E10: 7 | F10: Жэнь
A11: 10 | B11: 癸 | C11: 2 | D11: 5 | E11: 7 | F11: Гуй

Sheet Спр ворот
A1: id | B1: gate_cha | C1: gate_rus_1 | D1: gate_rus_2 | E1: id_element | F1: id_palace | G1: koef | H1: vstroika_in_gate
A2: 1 | B2: 休 | C2: Сю Мэнь | D2: Отдых | E2: 5 | F2: 1 | G2: 1 | H2: 1) расслабляться, отдыхать, кайфовать, восстанавливать силы в СПА, бассейне около водоема или попивая чай, пиво, вино 2) кататься на лодке, пойти в порт 3) чай, чайная лавка – пить, выбирать, посещать 4) рыба, морепродукты, водоросли – ловить, собирать, покупать, готовить 5) моряк, водолаз – общаться, стать им, одеться в форму и сделать селфи 6) заниматься сексом 7) моющее средство, шампунь – покупать, использовать
A3: 2 | B3: 生 | C3: Шэн Мэнь | D3: Жизнь | E3: 3 | F3: 8 | G3: 1 | H3: Все, что связано с деньгами и прибылью, а также рождением чего-то нового, торжеством жизни:1) Ребенок – играть с ним, гулять, заниматься, ухаживать за ним, пойти на детскую площадку 2) Нос, пальцы – обратить на них внимание 3) надеть перчатки 4) холм, гора, арка, тоннель – пойти в такое место 5) изделия из камня, керамика – делать, покупать, расписывать 6) деньги – считать, получать в кассе или банкомате
A4: 3 | B4: 傷 | C4: Шан Мэнь | D4: Ранение | E4: 1 | F4: 3 | G4: 0
A5: 4 | B5: 杜 | C5: Ду Мэнь | D5: Непроходимость | E5: 1 | F5: 4 | G5: 0
A6: 5 | B6: 景 | C6: Цзин Мэнь | D6: Сцена | E6: 2 | F6: 9 | G6: 0.75 | H6: Привлекать к себе внимание или участвовать в чем-то зрелищном: 1) Красивая женщина – выглядеть великолепно, отлично от большинства. 2) Либо идти вместе с красивой женщиной 3) Косметолог – посетить 4)офтальмолог – сходить к доктору 5) дворец, театр, кинотеатр – посетить 6) выйти на любую сцену, хоть деревянную в парке 7) доспехи надеть, в них сфотографироваться, посмеяться, отправить фото друзьям 8) красивый торт – купить и торжественно нести, дарить 9) потанцевать
A7: 6 | B7: 死 | C7: Сы Мэнь | D7: Смерть | E7: 3 | F7: 2 | G7: 0
A8: 7 | B8: 驚 | C8: Цзин Мэнь | D8: Шока | E8: 4 | F8: 7 | G8: 0
A9: 8 | B9: 開 | C9: Кай Мэнь | D9: Открытие | E9: 4 | F9: 6 | G9: 1 | H9: 1) шары из камня или металла – крутить в руках, привлекая внимание, желательно 6 штук. 2) можно запустить 6 (белых) воздушных шаров с гелием 3) корона – носить (в Бургер Кинге раздают) 4) голова – например взять с собой гипсовый бюст 5) зеркало (особенно круглое, овальное) – покупать, носить в руках, смотреться 6) старый человек – поговорить, спросить совета, помочь… 7) императорский дворец, президентская резиденция – посетить, сделать коллаж со своим фото… 8) памятник, статуя, особенно очень известная – подойти к ним 9) надеть белую одежду, обувь сумку, можно с металлическим отливом (если это необычно для вас или в том месте, куда вы направляетесь)

Sheet Rule
A1: в базу | B1: Описание | C1: lvl_1_nm | D1: lvl_2_nm | E1: lvl_3_nm | F1: lvl_4_nm | G1: lvl_5_nm | H1: lvl_6_nm | I1: lvl_1 | J1: lvl_2 | K1: lvl_3 | L1: lvl_4 | M1: lvl_5 | N1: lvl_6 | O1: lvl_7 | P1: gr | Q1: id | R1: nm | S1: des | T1: id_season_start | U1: god_stolp_sky | V1: god_stolp_sky_id_5_element | W1: god_stolp_earth | X1: god_stolp_earth_5_element | Y1: god_scdg_element_num | Z1: god_scdg_period_num | AA1: god_scdg_id_5_element | AB1: mes_stolp_sky | AC1: mes_stolp_sky_id_5_element | AD1: mes_stolp_earth | AE1: mes_stolp_earth_id_5_element | AF1: mes_scdg_element_num | AG1: mes_scdg_period_num | AH1: mes_scdg_id_5_element | AI1: den_stolp_sky | AJ1: den_stolp_sky_id_5_element | AK1: den_stolp_earth | AL1: den_stolp_earth_id_5_element | AM1: den_scdg_element_num | AN1: den_scdg_period_num | AO1: den_scdg_id_5_element | AP1: chas_stolp_sky | AQ1: chas_stolp_sky_id_5_element | AR1: chas_stolp_earth | AS1: chas_stolp_earth_id_5_element | AT1: chas_scdg_element_num | AU1: chas_scdg_period_num | AV1: chas_scdg_id_5_element | AW1: palace | AX1: flag_sky_fou_tou | AY1: sky | AZ1: flag_earth_fou_tou | BA1: earth | BB1: gate | BC1: flag_main_gate | BD1: star | BE1: flag_main_star | BF1: spirit | BG1: coef | BH1: activation_use | BI1: activation_stop_factor | BJ1: walk_use | BK1: walk_stop_factor | BL1: scdg_use | BM1: scdg_stop_factor | BN1: date_analyze_use | BO1: date_analyze_stop_factor
A2: 1 | B2: =_xlfn.CONCAT(C2,". ", D2,". ", E2,". ", F2,". ", G2,". ", H2) -> Общий расчет. Ци Мень. Анализ Дворца. Структуры. Благоприятность. Нет | C2: =IFERROR(VLOOKUP(I2,lvl_1[],2,FALSE),"Нет") -> Общий расчет | D2: =IFERROR(VLOOKUP(Rule!J2,lvl_2[],2,FALSE),"Нет") -> Ци Мень | E2: =IFERROR(VLOOKUP(Rule!K2,lvl_3[],2,FALSE),"Нет") -> Анализ Дворца | F2: =IFERROR(INDEX(lvl_4[],MATCH(L2,lvl_4[ID],0),MATCH(TEXT(K2,"##0"),lvl_4[#Headers],0)),"Нет") -> Структуры | G2: =IFERROR(INDEX(lvl_5[],MATCH(M2,lvl_5[ID],0),MATCH(_xlfn.CONCAT(TEXT(K2,"##0"),"_",TEXT(L2,"##0")),lvl_5[#Headers],0)),"Нет") -> Благоприятность | H2: =IFERROR(INDEX(lvl_6[],MATCH(N2,lvl_6[ID],0),MATCH(_xlfn.CONCAT(K2,"_",L2,"_",M2),lvl_6[#Headers],0)),"Нет") -> Нет | I2: 1 | J2: 2 | K2: 2 | L2: 1 | M2: 0 | N2: 0 | O2: =COUNTIF($P$2:P2,P2) -> 1 | P2: =_xlfn.CONCAT(I2, J2, K2, IF(LEN(L2)=1,_xlfn.CONCAT(0,L2),L2), IF(LEN(M2)=1,_xlfn.CONCAT(0,M2),M2), IF(LEN(N2)=1,_xlfn.CONCAT(0,N2),N2)) -> 122010000 | Q2: =_xlfn.CONCAT(I2, J2, K2, IF(LEN(L2)=1,_xlfn.CONCAT(0,L2),L2), IF(LEN(M2)=1,_xlfn.CONCAT(0,M2),M2), IF(LEN(N2)=1,_xlfn.CONCAT(0,N2),N2), IF(LEN(O2)=1,_xlfn.CONCAT("000",O2),IF(LEN(O2)=2,_xlfn.CONCAT("00",O2),IF(LEN(O2)=3,_xlfn.CONCAT(0,O2),O2)))) -> 1220100000001 | R2: Зеленый дракон поворачивает голову | S2: Огонь идет снизу-вверх. Используем, когда нужна поддержка. Действия принесут большую прибыль славу и богатство. Медленный старт, но потом устойчивый рост. Применяют для назначения на новый пост, начала судебного процесса в борьбе за правое дело, переезда, прибыльных проектов, строительства и всех позитивных дел. Не подходит для скрытых целей. | AY2: 戊 | BA2: 丙 | BG2: 1 | BJ2: 1
A3: 1 | B3: =_xlfn.CONCAT(C3,". ", D3,". ", E3,". ", F3,". ", G3,". ", H3) -> Общий расчет. Ци Мень. Анализ Дворца. Структуры. Благоприятность. Нет | C3: =IFERROR(VLOOKUP(I3,lvl_1[],2,FALSE),"Нет") -> Общий расчет | D3: =IFERROR(VLOOKUP(Rule!J3,lvl_2[],2,FALSE),"Нет") -> Ци Мень | E3: =IFERROR(VLOOKUP(Rule!K3,lvl_3[],2,FALSE),"Нет") -> Анализ Дворца | F3: =IFERROR(INDEX(lvl_4[],MATCH(L3,lvl_4[ID],0),MATCH(TEXT(K3,"##0"),lvl_4[#Headers],0)),"Нет") -> Структуры | G3: =IFERROR(INDEX(lvl_5[],MATCH(M3,lvl_5[ID],0),MATCH(_xlfn.CONCAT(TEXT(K3,"##0"),"_",TEXT(L3,"##0")),lvl_5[#Headers],0)),"Нет") -> Благоприятность | H3: =IFERROR(INDEX(lvl_6[],MATCH(N3,lvl_6[ID],0),MATCH(_xlfn.CONCAT(K3,"_",L3,"_",M3),lvl_6[#Headers],0)),"Нет") -> Нет | I3: 1 | J3: 2 | K3: 2 | L3: 1 | M3: 0 | N3: 0 | O3: =COUNTIF($P$2:P3,P3) -> 2 | P3: =_xlfn.CONCAT(I3, J3, K3, IF(LEN(L3)=1,_xlfn.CONCAT(0,L3),L3), IF(LEN(M3)=1,_xlfn.CONCAT(0,M3),M3), IF(LEN(N3)=1,_xlfn.CONCAT(0,N3),N3)) -> 122010000 | Q3: =_xlfn.CONCAT(I3, J3, K3, IF(LEN(L3)=1,_xlfn.CONCAT(0,L3),L3), IF(LEN(M3)=1,_xlfn.CONCAT(0,M3),M3), IF(LEN(N3)=1,_xlfn.CONCAT(0,N3),N3), IF(LEN(O3)=1,_xlfn.CONCAT("000",O3),IF(LEN(O3)=2,_xlfn.CONCAT("00",O3),IF(LEN(O3)=3,_xlfn.CONCAT(0,O3),O3)))) -> 1220100000002 | R3: Структура. Благоприятность. 003 甲/丙(Цзя/Бин). Зеленый дракон поворачивает голову | S3: Очень благоприятная комбинаци, любое действие приносит большую прибыль, славу и богатство. Благоприятно действовать. Однако если он встречает могилу или наказание - хорошая ситуация превращается в неблагоприятную | AX3: 1 | AY3: 戊 | BA3: 丙 | BG3: 1 | BJ3: 1
A4: 1 | B4: =_xlfn.CONCAT(C4,". ", D4,". ", E4,". ", F4,". ", G4,". ", H4) -> Общий расчет. Ци Мень. Анализ Дворца. Комбинации. Нет. Нет | C4: =IFERROR(VLOOKUP(I4,lvl_1[],2,FALSE),"Нет") -> Общий расчет | D4: =IFERROR(VLOOKUP(Rule!J4,lvl_2[],2,FALSE),"Нет") -> Ци Мень | E4: =IFERROR(VLOOKUP(Rule!K4,lvl_3[],2,FALSE),"Нет") -> Анализ Дворца | F4: =IFERROR(INDEX(lvl_4[],MATCH(L4,lvl_4[ID],0),MATCH(TEXT(K4,"##0"),lvl_4[#Headers],0)),"Нет") -> Комбинации | G4: =IFERROR(INDEX(lvl_5[],MATCH(M4,lvl_5[ID],0),MATCH(_xlfn.CONCAT(TEXT(K4,"##0"),"_",TEXT(L4,"##0")),lvl_5[#Headers],0)),"Нет") -> Нет | H4: =IFERROR(INDEX(lvl_6[],MATCH(N4,lvl_6[ID],0),MATCH(_xlfn.CONCAT(K4,"_",L4,"_",M4),lvl_6[#Headers],0)),"Нет") -> Нет | I4: 1 | J4: 2 | K4: 2 | L4: 2 | M4: 0 | N4: 0 | O4: =COUNTIF($P$2:P4,P4) -> 1 | P4: =_xlfn.CONCAT(I4, J4, K4, IF(LEN(L4)=1,_xlfn.CONCAT(0,L4),L4), IF(LEN(M4)=1,_xlfn.CONCAT(0,M4),M4), IF(LEN(N4)=1,_xlfn.CONCAT(0,N4),N4)) -> 122020000 | Q4: =_xlfn.CONCAT(I4, J4, K4, IF(LEN(L4)=1,_xlfn.CONCAT(0,L4),L4), IF(LEN(M4)=1,_xlfn.CONCAT(0,M4),M4), IF(LEN(N4)=1,_xlfn.CONCAT(0,N4),N4), IF(LEN(O4)=1,_xlfn.CONCAT("000",O4),IF(LEN(O4)=2,_xlfn.CONCAT("00",O4),IF(LEN(O4)=3,_xlfn.CONCAT(0,O4),O4)))) -> 1220200000001 | R4: Птица падает в гнездо | S4: Огонь приходит с неба, чтобы произвести землю. Мы получаем что-то с неба. Получение прибыли или награды без усилий. У всех вещей есть потенциал быть успешными. Можно замышлять большие дела. Подходит для продвижения по карьерной лестнице, прибыльных проектов, судебного процесса за правое дело, строительства, свадьбы и всех позитивных дел | AW4: 4 | AX4: 1 | AY4: 丙 | BA4: 戊 | BG4: 1 | BJ4: 1
A5: 1 | B5: =_xlfn.CONCAT(C5,". ", D5,". ", E5,". ", F5,". ", G5,". ", H5) -> Общий расчет. Ци Мень. Анализ Дворца. Комбинации. Нет. Нет | C5: =IFERROR(VLOOKUP(I5,lvl_1[],2,FALSE),"Нет") -> Общий расчет | D5: =IFERROR(VLOOKUP(Rule!J5,lvl_2[],2,FALSE),"Нет") -> Ци Мень | E5: =IFERROR(VLOOKUP(Rule!K5,lvl_3[],2,FALSE),"Нет") -> Анализ Дворца | F5: =IFERROR(INDEX(lvl_4[],MATCH(L5,lvl_4[ID],0),MATCH(TEXT(K5,"##0"),lvl_4[#Headers],0)),"Нет") -> Комбинации | G5: =IFERROR(INDEX(lvl_5[],MATCH(M5,lvl_5[ID],0),MATCH(_xlfn.CONCAT(TEXT(K5,"##0"),"_",TEXT(L5,"##0")),lvl_5[#Headers],0)),"Нет") -> Нет | H5: =IFERROR(INDEX(lvl_6[],MATCH(N5,lvl_6[ID],0),MATCH(_xlfn.CONCAT(K5,"_",L5,"_",M5),lvl_6[#Headers],0)),"Нет") -> Нет | I5: 1 | J5: 2 | K5: 2 | L5: 2 | M5: 0 | N5: 0 | O5: =COUNTIF($P$2:P5,P5) -> 2 | P5: =_xlfn.CONCAT(I5, J5, K5, IF(LEN(L5)=1,_xlfn.CONCAT(0,L5),L5), IF(LEN(M5)=1,_xlfn.CONCAT(0,M5),M5), IF(LEN(N5)=1,_xlfn.CONCAT(0,N5),N5)) -> 122020000 | Q5: =_xlfn.CONCAT(I5, J5, K5, IF(LEN(L5)=1,_xlfn.CONCAT(0,L5),L5), IF(LEN(M5)=1,_xlfn.CONCAT(0,M5),M5), IF(LEN(N5)=1,_xlfn.CONCAT(0,N5),N5), IF(LEN(O5)=1,_xlfn.CONCAT("000",O5),IF(LEN(O5)=2,_xlfn.CONCAT("00",O5),IF(LEN(O5)=3,_xlfn.CONCAT(0,O5),O5)))) -> 1220200000002 | R5: Три генерала допущены в главный зал | S5: Посредничество знатного человека поможет в денежных вопросах | AW5: 9 | AY5: 丙 | BB5: 生 | BG5: 1 | BJ5: 1
A6: 1 | B6: =_xlfn.CONCAT(C6,". ", D6,". ", E6,". ", F6,". ", G6,". ", H6) -> Общий расчет. Ци Мень. Анализ Дворца. Комбинации. Нет. Нет | C6: =IFERROR(VLOOKUP(I6,lvl_1[],2,FALSE),"Нет") -> Общий расчет | D6: =IFERROR(VLOOKUP(Rule!J6,lvl_2[],2,FALSE),"Нет") -> Ци Мень | E6: =IFERROR(VLOOKUP(Rule!K6,lvl_3[],2,FALSE),"Нет") -> Анализ Дворца | F6: =IFERROR(INDEX(lvl_4[],MATCH(L6,lvl_4[ID],0),MATCH(TEXT(K6,"##0"),lvl_4[#Headers],0)),"Нет") -> Комбинации | G6: =IFERROR(INDEX(lvl_5[],MATCH(M6,lvl_5[ID],0),MATCH(_xlfn.CONCAT(TEXT(K6,"##0"),"_",TEXT(L6,"##0")),lvl_5[#Headers],0)),"Нет") -> Нет | H6: =IFERROR(INDEX(lvl_6[],MATCH(N6,lvl_6[ID],0),MATCH(_xlfn.CONCAT(K6,"_",L6,"_",M6),lvl_6[#Headers],0)),"Нет") -> Нет | I6: 1 | J6: 2 | K6: 2 | L6: 2 | M6: 0 | N6: 0 | O6: =COUNTIF($P$2:P6,P6) -> 3 | P6: =_xlfn.CONCAT(I6, J6, K6, IF(LEN(L6)=1,_xlfn.CONCAT(0,L6),L6), IF(LEN(M6)=1,_xlfn.CONCAT(0,M6),M6), IF(LEN(N6)=1,_xlfn.CONCAT(0,N6),N6)) -> 122020000 | Q6: =_xlfn.CONCAT(I6, J6, K6, IF(LEN(L6)=1,_xlfn.CONCAT(0,L6),L6), IF(LEN(M6)=1,_xlfn.CONCAT(0,M6),M6), IF(LEN(N6)=1,_xlfn.CONCAT(0,N6),N6), IF(LEN(O6)=1,_xlfn.CONCAT("000",O6),IF(LEN(O6)=2,_xlfn.CONCAT("00",O6),IF(LEN(O6)=3,_xlfn.CONCAT(0,O6),O6)))) -> 1220200000003 | R6: Три генерала допущены в главный зал | S6: Посредничество знатного человека поможет в денежных вопросах | AW6: 9 | AY6: 丙 | BB6: 休 | BG6: 1 | BJ6: 1
A7: 1 | B7: =_xlfn.CONCAT(C7,". ", D7,". ", E7,". ", F7,". ", G7,". ", H7) -> Общий расчет. Ци Мень. Анализ Дворца. Комбинации. Нет. Нет | C7: =IFERROR(VLOOKUP(I7,lvl_1[],2,FALSE),"Нет") -> Общий расчет | D7: =IFERROR(VLOOKUP(Rule!J7,lvl_2[],2,FALSE),"Нет") -> Ци Мень | E7: =IFERROR(VLOOKUP(Rule!K7,lvl_3[],2,FALSE),"Нет") -> Анализ Дворца | F7: =IFERROR(INDEX(lvl_4[],MATCH(L7,lvl_4[ID],0),MATCH(TEXT(K7,"##0"),lvl_4[#Headers],0)),"Нет") -> Комбинации | G7: =IFERROR(INDEX(lvl_5[],MATCH(M7,lvl_5[ID],0),MATCH(_xlfn.CONCAT(TEXT(K7,"##0"),"_",TEXT(L7,"##0")),lvl_5[#Headers],0)),"Нет") -> Нет | H7: =IFERROR(INDEX(lvl_6[],MATCH(N7,lvl_6[ID],0),MATCH(_xlfn.CONCAT(K7,"_",L7,"_",M7),lvl_6[#Headers],0)),"Нет") -> Нет | I7: 1 | J7: 2 | K7: 2 | L7: 2 | M7: 0 | N7: 0 | O7: =COUNTIF($P$2:P7,P7) -> 4 | P7: =_xlfn.CONCAT(I7, J7, K7, IF(LEN(L7)=1,_xlfn.CONCAT(0,L7),L7), IF(LEN(M7)=1,_xlfn.CONCAT(0,M7),M7), IF(LEN(N7)=1,_xlfn.CONCAT(0,N7),N7)) -> 122020000 | Q7: =_xlfn.CONCAT(I7, J7, K7, IF(LEN(L7)=1,_xlfn.CONCAT(0,L7),L7), IF(LEN(M7)=1,_xlfn.CONCAT(0,M7),M7), IF(LEN(N7)=1,_xlfn.CONCAT(0,N7),N7), IF(LEN(O7)=1,_xlfn.CONCAT("000",O7),IF(LEN(O7)=2,_xlfn.CONCAT("00",O7),IF(LEN(O7)=3,_xlfn.CONCAT(0,O7),O7)))) -> 1220200000004 | R7: Три генерала допущены в главный зал | S7: Посредничество знатного человека поможет в денежных вопросах | AW7: 9 | AY7: 丙 | BB7: 開 | BG7: 1 | BJ7: 1
A8: 1 | B8: =_xlfn.CONCAT(C8,". ", D8,". ", E8,". ", F8,". ", G8,". ", H8) -> Общий расчет. Ци Мень. Анализ Дворца. Комбинации. Нет. Нет | C8: =IFERROR(VLOOKUP(I8,lvl_1[],2,FALSE),"Нет") -> Общий расчет | D8: =IFERROR(VLOOKUP(Rule!J8,lvl_2[],2,FALSE),"Нет") -> Ци Мень | E8: =IFERROR(VLOOKUP(Rule!K8,lvl_3[],2,FALSE),"Нет") -> Анализ Дворца | F8: =IFERROR(INDEX(lvl_4[],MATCH(L8,lvl_4[ID],0),MATCH(TEXT(K8,"##0"),lvl_4[#Headers],0)),"Нет") -> Комбинации | G8: =IFERROR(INDEX(lvl_5[],MATCH(M8,lvl_5[ID],0),MATCH(_xlfn.CONCAT(TEXT(K8,"##0"),"_",TEXT(L8,"##0")),lvl_5[#Headers],0)),"Нет") -> Нет | H8: =IFERROR(INDEX(lvl_6[],MATCH(N8,lvl_6[ID],0),MATCH(_xlfn.CONCAT(K8,"_",L8,"_",M8),lvl_6[#Headers],0)),"Нет") -> Нет | I8: 1 | J8: 2 | K8: 2 | L8: 2 | M8: 0 | N8: 0 | O8: =COUNTIF($P$2:P8,P8) -> 5 | P8: =_xlfn.CONCAT(I8, J8, K8, IF(LEN(L8)=1,_xlfn.CONCAT(0,L8),L8), IF(LEN(M8)=1,_xlfn.CONCAT(0,M8),M8), IF(LEN(N8)=1,_xlfn.CONCAT(0,N8),N8)) -> 122020000 | Q8: =_xlfn.CONCAT(I8, J8, K8, IF(LEN(L8)=1,_xlfn.CONCAT(0,L8),L8), IF(LEN(M8)=1,_xlfn.CONCAT(0,M8),M8), IF(LEN(N8)=1,_xlfn.CONCAT(0,N8),N8), IF(LEN(O8)=1,_xlfn.CONCAT("000",O8),IF(LEN(O8)=2,_xlfn.CONCAT("00",O8),IF(LEN(O8)=3,_xlfn.CONCAT(0,O8),O8)))) -> 1220200000005 | R8: Три генерала допущены в главный зал | S8: Посредничество знатного человека поможет в денежных вопросах | AW8: 7 | AY8: 丁 | BB8: 生 | BG8: 1 | BJ8: 1
A9: 1 | B9: =_xlfn.CONCAT(C9,". ", D9,". ", E9,". ", F9,". ", G9,". ", H9) -> Общий расчет. Ци Мень. Анализ Дворца. Комбинации. Нет. Нет | C9: =IFERROR(VLOOKUP(I9,lvl_1[],2,FALSE),"Нет") -> Общий расчет | D9: =IFERROR(VLOOKUP(Rule!J9,lvl_2[],2,FALSE),"Нет") -> Ци Мень | E9: =IFERROR(VLOOKUP(Rule!K9,lvl_3[],2,FALSE),"Нет") -> Анализ Дворца | F9: =IFERROR(INDEX(lvl_4[],MATCH(L9,lvl_4[ID],0),MATCH(TEXT(K9,"##0"),lvl_4[#Headers],0)),"Нет") -> Комбинации | G9: =IFERROR(INDEX(lvl_5[],MATCH(M9,lvl_5[ID],0),MATCH(_xlfn.CONCAT(TEXT(K9,"##0"),"_",TEXT(L9,"##0")),lvl_5[#Headers],0)),"Нет") -> Нет | H9: =IFERROR(INDEX(lvl_6[],MATCH(N9,lvl_6[ID],0),MATCH(_xlfn.CONCAT(K9,"_",L9,"_",M9),lvl_6[#Headers],0)),"Нет") -> Нет | I9: 1 | J9: 2 | K9: 2 | L9: 2 | M9: 0 | N9: 0 | O9: =COUNTIF($P$2:P9,P9) -> 6 | P9: =_xlfn.CONCAT(I9, J9, K9, IF(LEN(L9)=1,_xlfn.CONCAT(0,L9),L9), IF(LEN(M9)=1,_xlfn.CONCAT(0,M9),M9), IF(LEN(N9)=1,_xlfn.CONCAT(0,N9),N9)) -> 122020000 | Q9: =_xlfn.CONCAT(I9, J9, K9, IF(LEN(L9)=1,_xlfn.CONCAT(0,L9),L9), IF(LEN(M9)=1,_xlfn.CONCAT(0,M9),M9), IF(LEN(N9)=1,_xlfn.CONCAT(0,N9),N9), IF(LEN(O9)=1,_xlfn.CONCAT("000",O9),IF(LEN(O9)=2,_xlfn.CONCAT("00",O9),IF(LEN(O9)=3,_xlfn.CONCAT(0,O9),O9)))) -> 1220200000006 | R9: Три генерала допущены в главный зал | S9: Посредничество знатного человека поможет в денежных вопросах | AW9: 7 | AY9: 丁 | BB9: 休 | BG9: 1 | BJ9: 1
A10: 1 | B10: =_xlfn.CONCAT(C10,". ", D10,". ", E10,". ", F10,". ", G10,". ", H10) -> Общий расчет. Ци Мень. Анализ Дворца. Комбинации. Нет. Нет | C10: =IFERROR(VLOOKUP(I10,lvl_1[],2,FALSE),"Нет") -> Общий расчет | D10: =IFERROR(VLOOKUP(Rule!J10,lvl_2[],2,FALSE),"Нет") -> Ци Мень | E10: =IFERROR(VLOOKUP(Rule!K10,lvl_3[],2,FALSE),"Нет") -> Анализ Дворца | F10: =IFERROR(INDEX(lvl_4[],MATCH(L10,lvl_4[ID],0),MATCH(TEXT(K10,"##0"),lvl_4[#Headers],0)),"Нет") -> Комбинации | G10: =IFERROR(INDEX(lvl_5[],MATCH(M10,lvl_5[ID],0),MATCH(_xlfn.CONCAT(TEXT(K10,"##0"),"_",TEXT(L10,"##0")),lvl_5[#Headers],0)),"Нет") -> Нет | H10: =IFERROR(INDEX(lvl_6[],MATCH(N10,lvl_6[ID],0),MATCH(_xlfn.CONCAT(K10,"_",L10,"_",M10),lvl_6[#Headers],0)),"Нет") -> Нет | I10: 1 | J10: 2 | K10: 2 | L10: 2 | M10: 0 | N10: 0 | O10: =COUNTIF($P$2:P10,P10) -> 7 | P10: =_xlfn.CONCAT(I10, J10, K10, IF(LEN(L10)=1,_xlfn.CONCAT(0,L10),L10), IF(LEN(M10)=1,_xlfn.CONCAT(0,M10),M10), IF(LEN(N10)=1,_xlfn.CONCAT(0,N10),N10)) -> 122020000 | Q10: =_xlfn.CONCAT(I10, J10, K10, IF(LEN(L10)=1,_xlfn.CONCAT(0,L10),L10), IF(LEN(M10)=1,_xlfn.CONCAT(0,M10),M10), IF(LEN(N10)=1,_xlfn.CONCAT(0,N10),N10), IF(LEN(O10)=1,_xlfn.CONCAT("000",O10),IF(LEN(O10)=2,_xlfn.CONCAT("00",O10),IF(LEN(O10)=3,_xlfn.CONCAT(0,O10),O10)))) -> 1220200000007 | R10: Три генерала допущены в главный зал | S10: Посредничество знатного человека поможет в денежных вопросах | AW10: 7 | AY10: 丁 | BB10: 開 | BG10: 1 | BJ10: 1
A11: 1 | B11: =_xlfn.CONCAT(C11,". ", D11,". ", E11,". ", F11,". ", G11,". ", H11) -> Общий расчет. Ци Мень. Анализ Дворца. Комбинации. Нет. Нет | C11: =IFERROR(VLOOKUP(I11,lvl_1[],2,FALSE),"Нет") -> Общий расчет | D11: =IFERROR(VLOOKUP(Rule!J11,lvl_2[],2,FALSE),"Нет") -> Ци Мень | E11: =IFERROR(VLOOKUP(Rule!K11,lvl_3[],2,FALSE),"Нет") -> Анализ Дворца | F11: =IFERROR(INDEX(lvl_4[],MATCH(L11,lvl_4[ID],0),MATCH(TEXT(K11,"##0"),lvl_4[#Headers],0)),"Нет") -> Комбинации | G11: =IFERROR(INDEX(lvl_5[],MATCH(M11,lvl_5[ID],0),MATCH(_xlfn.CONCAT(TEXT(K11,"##0"),"_",TEXT(L11,"##0")),lvl_5[#Headers],0)),"Нет") -> Нет | H11: =IFERROR(INDEX(lvl_6[],MATCH(N11,lvl_6[ID],0),MATCH(_xlfn.CONCAT(K11,"_",L11,"_",M11),lvl_6[#Headers],0)),"Нет") -> Нет | I11: 1 | J11: 2 | K11: 2 | L11: 2 | M11: 0 | N11: 0 | O11: =COUNTIF($P$2:P11,P11) -> 8 | P11: =_xlfn.CONCAT(I11, J11, K11, IF(LEN(L11)=1,_xlfn.CONCAT(0,L11),L11), IF(LEN(M11)=1,_xlfn.CONCAT(0,M11),M11), IF(LEN(N11)=1,_xlfn.CONCAT(0,N11),N11)) -> 122020000 | Q11: =_xlfn.CONCAT(I11, J11, K11, IF(LEN(L11)=1,_xlfn.CONCAT(0,L11),L11), IF(LEN(M11)=1,_xlfn.CONCAT(0,M11),M11), IF(LEN(N11)=1,_xlfn.CONCAT(0,N11),N11), IF(LEN(O11)=1,_xlfn.CONCAT("000",O11),IF(LEN(O11)=2,_xlfn.CONCAT("00",O11),IF(LEN(O11)=3,_xlfn.CONCAT(0,O11),O11)))) -> 1220200000008 | R11: Три генерала допущены в главный зал | S11: Посредничество знатного человека поможет в денежных вопросах | AW11: 3 | AY11: 乙 | BB11: 生 | BG11: 1 | BJ11: 1
A12: 1 | B12: =_xlfn.CONCAT(C12,". ", D12,". ", E12,". ", F12,". ", G12,". ", H12) -> Общий расчет. Ци Мень. Анализ Дворца. Комбинации. Нет. Нет | C12: =IFERROR(VLOOKUP(I12,lvl_1[],2,FALSE),"Нет") -> Общий расчет | D12: =IFERROR(VLOOKUP(Rule!J12,lvl_2[],2,FALSE),"Нет") -> Ци Мень | E12: =IFERROR(VLOOKUP(Rule!K12,lvl_3[],2,FALSE),"Нет") -> Анализ Дворца | F12: =IFERROR(INDEX(lvl_4[],MATCH(L12,lvl_4[ID],0),MATCH(TEXT(K12,"##0"),lvl_4[#Headers],0)),"Нет") -> Комбинации | G12: =IFERROR(INDEX(lvl_5[],MATCH(M12,lvl_5[ID],0),MATCH(_xlfn.CONCAT(TEXT(K12,"##0"),"_",TEXT(L12,"##0")),lvl_5[#Headers],0)),"Нет") -> Нет | H12: =IFERROR(INDEX(lvl_6[],MATCH(N12,lvl_6[ID],0),MATCH(_xlfn.CONCAT(K12,"_",L12,"_",M12),lvl_6[#Headers],0)),"Нет") -> Нет | I12: 1 | J12: 2 | K12: 2 | L12: 2 | M12: 0 | N12: 0 | O12: =COUNTIF($P$2:P12,P12) -> 9 | P12: =_xlfn.CONCAT(I12, J12, K12, IF(LEN(L12)=1,_xlfn.CONCAT(0,L12),L12), IF(LEN(M12)=1,_xlfn.CONCAT(0,M12),M12), IF(LEN(N12)=1,_xlfn.CONCAT(0,N12),N12)) -> 122020000 | Q12: =_xlfn.CONCAT(I12, J12, K12, IF(LEN(L12)=1,_xlfn.CONCAT(0,L12),L12), IF(LEN(M12)=1,_xlfn.CONCAT(0,M12),M12), IF(LEN(N12)=1,_xlfn.CONCAT(0,N12),N12), IF(LEN(O12)=1,_xlfn.CONCAT("000",O12),IF(LEN(O12)=2,_xlfn.CONCAT("00",O12),IF(LEN(O12)=3,_xlfn.CONCAT(0,O12),O12)))) -> 1220200000009 | R12: Три генерала допущены в главный зал | S12: Посредничество знатного человека поможет в денежных вопросах | AW12: 3 | AY12: 乙 | BB12: 休 | BG12: 1 | BJ12: 1
A13: 1 | B13: =_xlfn.CONCAT(C13,". ", D13,". ", E13,". ", F13,". ", G13,". ", H13) -> Общий расчет. Ци Мень. Анализ Дворца. Комбинации. Нет. Нет | C13: =IFERROR(VLOOKUP(I13,lvl_1[],2,FALSE),"Нет") -> Общий расчет | D13: =IFERROR(VLOOKUP(Rule!J13,lvl_2[],2,FALSE),"Нет") -> Ци Мень | E13: =IFERROR(VLOOKUP(Rule!K13,lvl_3[],2,FALSE),"Нет") -> Анализ Дворца | F13: =IFERROR(INDEX(lvl_4[],MATCH(L13,lvl_4[ID],0),MATCH(TEXT(K13,"##0"),lvl_4[#Headers],0)),"Нет") -> Комбинации | G13: =IFERROR(INDEX(lvl_5[],MATCH(M13,lvl_5[ID],0),MATCH(_xlfn.CONCAT(TEXT(K13,"##0"),"_",TEXT(L13,"##0")),lvl_5[#Headers],0)),"Нет") -> Нет | H13: =IFERROR(INDEX(lvl_6[],MATCH(N13,lvl_6[ID],0),MATCH(_xlfn.CONCAT(K13,"_",L13,"_",M13),lvl_6[#Headers],0)),"Нет") -> Нет | I13: 1 | J13: 2 | K13: 2 | L13: 2 | M13: 0 | N13: 0 | O13: =COUNTIF($P$2:P13,P13) -> 10 | P13: =_xlfn.CONCAT(I13, J13, K13, IF(LEN(L13)=1,_xlfn.CONCAT(0,L13),L13), IF(LEN(M13)=1,_xlfn.CONCAT(0,M13),M13), IF(LEN(N13)=1,_xlfn.CONCAT(0,N13),N13)) -> 122020000 | Q13: =_xlfn.CONCAT(I13, J13, K13, IF(LEN(L13)=1,_xlfn.CONCAT(0,L13),L13), IF(LEN(M13)=1,_xlfn.CONCAT(0,M13),M13), IF(LEN(N13)=1,_xlfn.CONCAT(0,N13),N13), IF(LEN(O13)=1,_xlfn.CONCAT("000",O13),IF(LEN(O13)=2,_xlfn.CONCAT("00",O13),IF(LEN(O13)=3,_xlfn.CONCAT(0,O13),O13)))) -> 1220200000010 | R13: Три генерала допущены в главный зал | S13: Посредничество знатного человека поможет в денежных вопросах | AW13: 3 | AY13: 乙 | BB13: 開 | BG13: 1 | BJ13: 1
A14: 1 | B14: =_xlfn.CONCAT(C14,". ", D14,". ", E14,". ", F14,". ", G14,". ", H14) -> Общий расчет. Ци Мень. Анализ Дворца. Комбинации. Нет. Нет | C14: =IFERROR(VLOOKUP(I14,lvl_1[],2,FALSE),"Нет") -> Общий расчет | D14: =IFERROR(VLOOKUP(Rule!J14,lvl_2[],2,FALSE),"Нет") -> Ци Мень | E14: =IFERROR(VLOOKUP(Rule!K14,lvl_3[],2,FALSE),"Нет") -> Анализ Дворца | F14: =IFERROR(INDEX(lvl_4[],MATCH(L14,lvl_4[ID],0),MATCH(TEXT(K14,"##0"),lvl_4[#Headers],0)),"Нет") -> Комбинации | G14: =IFERROR(INDEX(lvl_5[],MATCH(M14,lvl_5[ID],0),MATCH(_xlfn.CONCAT(TEXT(K14,"##0"),"_",TEXT(L14,"##0")),lvl_5[#Headers],0)),"Нет") -> Нет | H14: =IFERROR(INDEX(lvl_6[],MATCH(N14,lvl_6[ID],0),MATCH(_xlfn.CONCAT(K14,"_",L14,"_",M14),lvl_6[#Headers],0)),"Нет") -> Нет | I14: 1 | J14: 2 | K14: 2 | L14: 2 | M14: 0 | N14: 0 | O14: =COUNTIF($P$2:P14,P14) -> 11 | P14: =_xlfn.CONCAT(I14, J14, K14, IF(LEN(L14)=1,_xlfn.CONCAT(0,L14),L14), IF(LEN(M14)=1,_xlfn.CONCAT(0,M14),M14), IF(LEN(N14)=1,_xlfn.CONCAT(0,N14),N14)) -> 122020000 | Q14: =_xlfn.CONCAT(I14, J14, K14, IF(LEN(L14)=1,_xlfn.CONCAT(0,L14),L14), IF(LEN(M14)=1,_xlfn.CONCAT(0,M14),M14), IF(LEN(N14)=1,_xlfn.CONCAT(0,N14),N14), IF(LEN(O14)=1,_xlfn.CONCAT("000",O14),IF(LEN(O14)=2,_xlfn.CONCAT("00",O14),IF(LEN(O14)=3,_xlfn.CONCAT(0,O14),O14)))) -> 1220200000011 | R14: 9 Дунь. Человеческая структура (Рэн Дунь – Ren Dun) | S14: Энергия для решения проблем и устранения негатива в человеческих отношениях, для поиска помощи, получения рекомендаций, назначения свиданий, сватовства, брака, переговоров, тайных договоров, торговли и финансовых сделок | AY14: 乙 | BB14: 休 | BF14: 合 | BG14: 1 | BJ14: 1
A15: 1 | B15: =_xlfn.CONCAT(C15,". ", D15,". ", E15,". ", F15,". ", G15,". ", H15) -> Общий расчет. Ци Мень. Анализ Дворца. Комбинации. Нет. Нет | C15: =IFERROR(VLOOKUP(I15,lvl_1[],2,FALSE),"Нет") -> Общий расчет | D15: =IFERROR(VLOOKUP(Rule!J15,lvl_2[],2,FALSE),"Нет") -> Ци Мень | E15: =IFERROR(VLOOKUP(Rule!K15,lvl_3[],2,FALSE),"Нет") -> Анализ Дворца | F15: =IFERROR(INDEX(lvl_4[],MATCH(L15,lvl_4[ID],0),MATCH(TEXT(K15,"##0"),lvl_4[#Headers],0)),"Нет") -> Комбинации | G15: =IFERROR(INDEX(lvl_5[],MATCH(M15,lvl_5[ID],0),MATCH(_xlfn.CONCAT(TEXT(K15,"##0"),"_",TEXT(L15,"##0")),lvl_5[#Headers],0)),"Нет") -> Нет | H15: =IFERROR(INDEX(lvl_6[],MATCH(N15,lvl_6[ID],0),MATCH(_xlfn.CONCAT(K15,"_",L15,"_",M15),lvl_6[#Headers],0)),"Нет") -> Нет | I15: 1 | J15: 2 | K15: 2 | L15: 2 | M15: 0 | N15: 0 | O15: =COUNTIF($P$2:P15,P15) -> 12 | P15: =_xlfn.CONCAT(I15, J15, K15, IF(LEN(L15)=1,_xlfn.CONCAT(0,L15),L15), IF(LEN(M15)=1,_xlfn.CONCAT(0,M15),M15), IF(LEN(N15)=1,_xlfn.CONCAT(0,N15),N15)) -> 122020000 | Q15: =_xlfn.CONCAT(I15, J15, K15, IF(LEN(L15)=1,_xlfn.CONCAT(0,L15),L15), IF(LEN(M15)=1,_xlfn.CONCAT(0,M15),M15), IF(LEN(N15)=1,_xlfn.CONCAT(0,N15),N15), IF(LEN(O15)=1,_xlfn.CONCAT("000",O15),IF(LEN(O15)=2,_xlfn.CONCAT("00",O15),IF(LEN(O15)=3,_xlfn.CONCAT(0,O15),O15)))) -> 1220200000012 | R15: 9 Дунь. Человеческая структура (Рэн Дунь – Ren Dun) | S15: Энергия для решения проблем и устранения негатива в человеческих отношениях, для поиска помощи, получения рекомендаций, назначения свиданий, сватовства, брака, переговоров, тайных договоров, торговли и финансовых сделок | AY15: 乙 | BB15: 生 | BF15: 合 | BG15: 1 | BJ15: 1
A16: 1 | B16: =_xlfn.CONCAT(C16,". ", D16,". ", E16,". ", F16,". ", G16,". ", H16) -> Общий расчет. Ци Мень. Анализ Дворца. Комбинации. Нет. Нет | C16: =IFERROR(VLOOKUP(I16,lvl_1[],2,FALSE),"Нет") -> Общий расчет | D16: =IFERROR(VLOOKUP(Rule!J16,lvl_2[],2,FALSE),"Нет") -> Ци Мень | E16: =IFERROR(VLOOKUP(Rule!K16,lvl_3[],2,FALSE),"Нет") -> Анализ Дворца | F16: =IFERROR(INDEX(lvl_4[],MATCH(L16,lvl_4[ID],0),MATCH(TEXT(K16,"##0"),lvl_4[#Headers],0)),"Нет") -> Комбинации | G16: =IFERROR(INDEX(lvl_5[],MATCH(M16,lvl_5[ID],0),MATCH(_xlfn.CONCAT(TEXT(K16,"##0"),"_",TEXT(L16,"##0")),lvl_5[#Headers],0)),"Нет") -> Нет | H16: =IFERROR(INDEX(lvl_6[],MATCH(N16,lvl_6[ID],0),MATCH(_xlfn.CONCAT(K16,"_",L16,"_",M16),lvl_6[#Headers],0)),"Нет") -> Нет | I16: 1 | J16: 2 | K16: 2 | L16: 2 | M16: 0 | N16: 0 | O16: =COUNTIF($P$2:P16,P16) -> 13 | P16: =_xlfn.CONCAT(I16, J16, K16, IF(LEN(L16)=1,_xlfn.CONCAT(0,L16),L16), IF(LEN(M16)=1,_xlfn.CONCAT(0,M16),M16), IF(LEN(N16)=1,_xlfn.CONCAT(0,N16),N16)) -> 122020000 | Q16: =_xlfn.CONCAT(I16, J16, K16, IF(LEN(L16)=1,_xlfn.CONCAT(0,L16),L16), IF(LEN(M16)=1,_xlfn.CONCAT(0,M16),M16), IF(LEN(N16)=1,_xlfn.CONCAT(0,N16),N16), IF(LEN(O16)=1,_xlfn.CONCAT("000",O16),IF(LEN(O16)=2,_xlfn.CONCAT("00",O16),IF(LEN(O16)=3,_xlfn.CONCAT(0,O16),O16)))) -> 1220200000013 | R16: 9 Дунь. Человеческая структура (Рэн Дунь – Ren Dun) | S16: Энергия для решения проблем и устранения негатива в человеческих отношениях, для поиска помощи, получения рекомендаций, назначения свиданий, сватовства, брака, переговоров, тайных договоров, торговли и финансовых сделок | AY16: 乙 | BB16: 開 | BF16: 合 | BG16: 1 | BJ16: 1
A17: 1 | B17: =_xlfn.CONCAT(C17,". ", D17,". ", E17,". ", F17,". ", G17,". ", H17) -> Общий расчет. Ци Мень. Анализ Дворца. Комбинации. Нет. Нет | C17: =IFERROR(VLOOKUP(I17,lvl_1[],2,FALSE),"Нет") -> Общий расчет | D17: =IFERROR(VLOOKUP(Rule!J17,lvl_2[],2,FALSE),"Нет") -> Ци Мень | E17: =IFERROR(VLOOKUP(Rule!K17,lvl_3[],2,FALSE),"Нет") -> Анализ Дворца | F17: =IFERROR(INDEX(lvl_4[],MATCH(L17,lvl_4[ID],0),MATCH(TEXT(K17,"##0"),lvl_4[#Headers],0)),"Нет") -> Комбинации | G17: =IFERROR(INDEX(lvl_5[],MATCH(M17,lvl_5[ID],0),MATCH(_xlfn.CONCAT(TEXT(K17,"##0"),"_",TEXT(L17,"##0")),lvl_5[#Headers],0)),"Нет") -> Нет | H17: =IFERROR(INDEX(lvl_6[],MATCH(N17,lvl_6[ID],0),MATCH(_xlfn.CONCAT(K17,"_",L17,"_",M17),lvl_6[#Headers],0)),"Нет") -> Нет | I17: 1 | J17: 2 | K17: 2 | L17: 2 | M17: 0 | N17: 0 | O17: =COUNTIF($P$2:P17,P17) -> 14 | P17: =_xlfn.CONCAT(I17, J17, K17, IF(LEN(L17)=1,_xlfn.CONCAT(0,L17),L17), IF(LEN(M17)=1,_xlfn.CONCAT(0,M17),M17), IF(LEN(N17)=1,_xlfn.CONCAT(0,N17),N17)) -> 122020000 | Q17: =_xlfn.CONCAT(I17, J17, K17, IF(LEN(L17)=1,_xlfn.CONCAT(0,L17),L17), IF(LEN(M17)=1,_xlfn.CONCAT(0,M17),M17), IF(LEN(N17)=1,_xlfn.CONCAT(0,N17),N17), IF(LEN(O17)=1,_xlfn.CONCAT("000",O17),IF(LEN(O17)=2,_xlfn.CONCAT("00",O17),IF(LEN(O17)=3,_xlfn.CONCAT(0,O17),O17)))) -> 1220200000014 | R17: 9 Дунь. Человеческая структура (Рэн Дунь – Ren Dun) | S17: Энергия для решения проблем и устранения негатива в человеческих отношениях, для поиска помощи, получения рекомендаций, назначения свиданий, сватовства, брака, переговоров, тайных договоров, торговли и финансовых сделок | AY17: 丙 | BB17: 休 | BF17: 合 | BG17: 1 | BJ17: 1
A18: 1 | B18: =_xlfn.CONCAT(C18,". ", D18,". ", E18,". ", F18,". ", G18,". ", H18) -> Общий расчет. Ци Мень. Анализ Дворца. Комбинации. Нет. Нет | C18: =IFERROR(VLOOKUP(I18,lvl_1[],2,FALSE),"Нет") -> Общий расчет | D18: =IFERROR(VLOOKUP(Rule!J18,lvl_2[],2,FALSE),"Нет") -> Ци Мень | E18: =IFERROR(VLOOKUP(Rule!K18,lvl_3[],2,FALSE),"Нет") -> Анализ Дворца | F18: =IFERROR(INDEX(lvl_4[],MATCH(L18,lvl_4[ID],0),MATCH(TEXT(K18,"##0"),lvl_4[#Headers],0)),"Нет") -> Комбинации | G18: =IFERROR(INDEX(lvl_5[],MATCH(M18,lvl_5[ID],0),MATCH(_xlfn.CONCAT(TEXT(K18,"##0"),"_",TEXT(L18,"##0")),lvl_5[#Headers],0)),"Нет") -> Нет | H18: =IFERROR(INDEX(lvl_6[],MATCH(N18,lvl_6[ID],0),MATCH(_xlfn.CONCAT(K18,"_",L18,"_",M18),lvl_6[#Headers],0)),"Нет") -> Нет | I18: 1 | J18: 2 | K18: 2 | L18: 2 | M18: 0 | N18: 0 | O18: =COUNTIF($P$2:P18,P18) -> 15 | P18: =_xlfn.CONCAT(I18, J18, K18, IF(LEN(L18)=1,_xlfn.CONCAT(0,L18),L18), IF(LEN(M18)=1,_xlfn.CONCAT(0,M18),M18), IF(LEN(N18)=1,_xlfn.CONCAT(0,N18),N18)) -> 122020000 | Q18: =_xlfn.CONCAT(I18, J18, K18, IF(LEN(L18)=1,_xlfn.CONCAT(0,L18),L18), IF(LEN(M18)=1,_xlfn.CONCAT(0,M18),M18), IF(LEN(N18)=1,_xlfn.CONCAT(0,N18),N18), IF(LEN(O18)=1,_xlfn.CONCAT("000",O18),IF(LEN(O18)=2,_xlfn.CONCAT("00",O18),IF(LEN(O18)=3,_xlfn.CONCAT(0,O18),O18)))) -> 1220200000015 | R18: 9 Дунь. Человеческая структура (Рэн Дунь – Ren Dun) | S18: Энергия для решения проблем и устранения негатива в человеческих отношениях, для поиска помощи, получения рекомендаций, назначения свиданий, сватовства, брака, переговоров, тайных договоров, торговли и финансовых сделок | AY18: 丙 | BB18: 生 | BF18: 合 | BG18: 1 | BJ18: 1
A19: 1 | B19: =_xlfn.CONCAT(C19,". ", D19,". ", E19,". ", F19,". ", G19,". ", H19) -> Общий расчет. Ци Мень. Анализ Дворца. Комбинации. Нет. Нет | C19: =IFERROR(VLOOKUP(I19,lvl_1[],2,FALSE),"Нет") -> Общий расчет | D19: =IFERROR(VLOOKUP(Rule!J19,lvl_2[],2,FALSE),"Нет") -> Ци Мень | E19: =IFERROR(VLOOKUP(Rule!K19,lvl_3[],2,FALSE),"Нет") -> Анализ Дворца | F19: =IFERROR(INDEX(lvl_4[],MATCH(L19,lvl_4[ID],0),MATCH(TEXT(K19,"##0"),lvl_4[#Headers],0)),"Нет") -> Комбинации | G19: =IFERROR(INDEX(lvl_5[],MATCH(M19,lvl_5[ID],0),MATCH(_xlfn.CONCAT(TEXT(K19,"##0"),"_",TEXT(L19,"##0")),lvl_5[#Headers],0)),"Нет") -> Нет | H19: =IFERROR(INDEX(lvl_6[],MATCH(N19,lvl_6[ID],0),MATCH(_xlfn.CONCAT(K19,"_",L19,"_",M19),lvl_6[#Headers],0)),"Нет") -> Нет | I19: 1 | J19: 2 | K19: 2 | L19: 2 | M19: 0 | N19: 0 | O19: =COUNTIF($P$2:P19,P19) -> 16 | P19: =_xlfn.CONCAT(I19, J19, K19, IF(LEN(L19)=1,_xlfn.CONCAT(0,L19),L19), IF(LEN(M19)=1,_xlfn.CONCAT(0,M19),M19), IF(LEN(N19)=1,_xlfn.CONCAT(0,N19),N19)) -> 122020000 | Q19: =_xlfn.CONCAT(I19, J19, K19, IF(LEN(L19)=1,_xlfn.CONCAT(0,L19),L19), IF(LEN(M19)=1,_xlfn.CONCAT(0,M19),M19), IF(LEN(N19)=1,_xlfn.CONCAT(0,N19),N19), IF(LEN(O19)=1,_xlfn.CONCAT("000",O19),IF(LEN(O19)=2,_xlfn.CONCAT("00",O19),IF(LEN(O19)=3,_xlfn.CONCAT(0,O19),O19)))) -> 1220200000016 | R19: 9 Дунь. Человеческая структура (Рэн Дунь – Ren Dun) | S19: Энергия для решения проблем и устранения негатива в человеческих отношениях, для поиска помощи, получения рекомендаций, назначения свиданий, сватовства, брака, переговоров, тайных договоров, торговли и финансовых сделок | AY19: 丙 | BB19: 開 | BF19: 合 | BG19: 1 | BJ19: 1
A20: 1 | B20: =_xlfn.CONCAT(C20,". ", D20,". ", E20,". ", F20,". ", G20,". ", H20) -> Общий расчет. Ци Мень. Анализ Дворца. Комбинации. Нет. Нет | C20: =IFERROR(VLOOKUP(I20,lvl_1[],2,FALSE),"Нет") -> Общий расчет | D20: =IFERROR(VLOOKUP(Rule!J20,lvl_2[],2,FALSE),"Нет") -> Ци Мень | E20: =IFERROR(VLOOKUP(Rule!K20,lvl_3[],2,FALSE),"Нет") -> Анализ Дворца | F20: =IFERROR(INDEX(lvl_4[],MATCH(L20,lvl_4[ID],0),MATCH(TEXT(K20,"##0"),lvl_4[#Headers],0)),"Нет") -> Комбинации | G20: =IFERROR(INDEX(lvl_5[],MATCH(M20,lvl_5[ID],0),MATCH(_xlfn.CONCAT(TEXT(K20,"##0"),"_",TEXT(L20,"##0")),lvl_5[#Headers],0)),"Нет") -> Нет | H20: =IFERROR(INDEX(lvl_6[],MATCH(N20,lvl_6[ID],0),MATCH(_xlfn.CONCAT(K20,"_",L20,"_",M20),lvl_6[#Headers],0)),"Нет") -> Нет | I20: 1 | J20: 2 | K20: 2 | L20: 2 | M20: 0 | N20: 0 | O20: =COUNTIF($P$2:P20,P20) -> 17 | P20: =_xlfn.CONCAT(I20, J20, K20, IF(LEN(L20)=1,_xlfn.CONCAT(0,L20),L20), IF(LEN(M20)=1,_xlfn.CONCAT(0,M20),M20), IF(LEN(N20)=1,_xlfn.CONCAT(0,N20),N20)) -> 122020000 | Q20: =_xlfn.CONCAT(I20, J20, K20, IF(LEN(L20)=1,_xlfn.CONCAT(0,L20),L20), IF(LEN(M20)=1,_xlfn.CONCAT(0,M20),M20), IF(LEN(N20)=1,_xlfn.CONCAT(0,N20),N20), IF(LEN(O20)=1,_xlfn.CONCAT("000",O20),IF(LEN(O20)=2,_xlfn.CONCAT("00",O20),IF(LEN(O20)=3,_xlfn.CONCAT(0,O20),O20)))) -> 1220200000017 | R20: 9 Дунь. Человеческая структура (Рэн Дунь – Ren Dun) | S20: Энергия для решения проблем и устранения негатива в человеческих отношениях, для поиска помощи, получения рекомендаций, назначения свиданий, сватовства, брака, переговоров, тайных договоров, торговли и финансовых сделок | AY20: 丁 | BB20: 休 | BF20: 合 | BG20: 1 | BJ20: 1
A21: 1 | B21: =_xlfn.CONCAT(C21,". ", D21,". ", E21,". ", F21,". ", G21,". ", H21) -> Общий расчет. Ци Мень. Анализ Дворца. Комбинации. Нет. Нет | C21: =IFERROR(VLOOKUP(I21,lvl_1[],2,FALSE),"Нет") -> Общий расчет | D21: =IFERROR(VLOOKUP(Rule!J21,lvl_2[],2,FALSE),"Нет") -> Ци Мень | E21: =IFERROR(VLOOKUP(Rule!K21,lvl_3[],2,FALSE),"Нет") -> Анализ Дворца | F21: =IFERROR(INDEX(lvl_4[],MATCH(L21,lvl_4[ID],0),MATCH(TEXT(K21,"##0"),lvl_4[#Headers],0)),"Нет") -> Комбинации | G21: =IFERROR(INDEX(lvl_5[],MATCH(M21,lvl_5[ID],0),MATCH(_xlfn.CONCAT(TEXT(K21,"##0"),"_",TEXT(L21,"##0")),lvl_5[#Headers],0)),"Нет") -> Нет | H21: =IFERROR(INDEX(lvl_6[],MATCH(N21,lvl_6[ID],0),MATCH(_xlfn.CONCAT(K21,"_",L21,"_",M21),lvl_6[#Headers],0)),"Нет") -> Нет | I21: 1 | J21: 2 | K21: 2 | L21: 2 | M21: 0 | N21: 0 | O21: =COUNTIF($P$2:P21,P21) -> 18 | P21: =_xlfn.CONCAT(I21, J21, K21, IF(LEN(L21)=1,_xlfn.CONCAT(0,L21),L21), IF(LEN(M21)=1,_xlfn.CONCAT(0,M21),M21), IF(LEN(N21)=1,_xlfn.CONCAT(0,N21),N21)) -> 122020000 | Q21: =_xlfn.CONCAT(I21, J21, K21, IF(LEN(L21)=1,_xlfn.CONCAT(0,L21),L21), IF(LEN(M21)=1,_xlfn.CONCAT(0,M21),M21), IF(LEN(N21)=1,_xlfn.CONCAT(0,N21),N21), IF(LEN(O21)=1,_xlfn.CONCAT("000",O21),IF(LEN(O21)=2,_xlfn.CONCAT("00",O21),IF(LEN(O21)=3,_xlfn.CONCAT(0,O21),O21)))) -> 1220200000018 | R21: 9 Дунь. Человеческая структура (Рэн Дунь – Ren Dun) | S21: Энергия для решения проблем и устранения негатива в человеческих отношениях, для поиска помощи, получения рекомендаций, назначения свиданий, сватовства, брака, переговоров, тайных договоров, торговли и финансовых сделок | AY21: 丁 | BB21: 生 | BF21: 合 | BG21: 1 | BJ21: 1
A22: 1 | B22: =_xlfn.CONCAT(C22,". ", D22,". ", E22,". ", F22,". ", G22,". ", H22) -> Общий расчет. Ци Мень. Анализ Дворца. Комбинации. Нет. Нет | C22: =IFERROR(VLOOKUP(I22,lvl_1[],2,FALSE),"Нет") -> Общий расчет | D22: =IFERROR(VLOOKUP(Rule!J22,lvl_2[],2,FALSE),"Нет") -> Ци Мень | E22: =IFERROR(VLOOKUP(Rule!K22,lvl_3[],2,FALSE),"Нет") -> Анализ Дворца | F22: =IFERROR(INDEX(lvl_4[],MATCH(L22,lvl_4[ID],0),MATCH(TEXT(K22,"##0"),lvl_4[#Headers],0)),"Нет") -> Комбинации | G22: =IFERROR(INDEX(lvl_5[],MATCH(M22,lvl_5[ID],0),MATCH(_xlfn.CONCAT(TEXT(K22,"##0"),"_",TEXT(L22,"##0")),lvl_5[#Headers],0)),"Нет") -> Нет | H22: =IFERROR(INDEX(lvl_6[],MATCH(N22,lvl_6[ID],0),MATCH(_xlfn.CONCAT(K22,"_",L22,"_",M22),lvl_6[#Headers],0)),"Нет") -> Нет | I22: 1 | J22: 2 | K22: 2 | L22: 2 | M22: 0 | N22: 0 | O22: =COUNTIF($P$2:P22,P22) -> 19 | P22: =_xlfn.CONCAT(I22, J22, K22, IF(LEN(L22)=1,_xlfn.CONCAT(0,L22),L22), IF(LEN(M22)=1,_xlfn.CONCAT(0,M22),M22), IF(LEN(N22)=1,_xlfn.CONCAT(0,N22),N22)) -> 122020000 | Q22: =_xlfn.CONCAT(I22, J22, K22, IF(LEN(L22)=1,_xlfn.CONCAT(0,L22),L22), IF(LEN(M22)=1,_xlfn.CONCAT(0,M22),M22), IF(LEN(N22)=1,_xlfn.CONCAT(0,N22),N22), IF(LEN(O22)=1,_xlfn.CONCAT("000",O22),IF(LEN(O22)=2,_xlfn.CONCAT("00",O22),IF(LEN(O22)=3,_xlfn.CONCAT(0,O22),O22)))) -> 1220200000019 | R22: 9 Дунь. Человеческая структура (Рэн Дунь – Ren Dun) | S22: Энергия для решения проблем и устранения негатива в человеческих отношениях, для поиска помощи, получения рекомендаций, назначения свиданий, сватовства, брака, переговоров, тайных договоров, торговли и финансовых сделок | AY22: 丁 | BB22: 開 | BF22: 合 | BG22: 1 | BJ22: 1
A23: 1 | B23: =_xlfn.CONCAT(C23,". ", D23,". ", E23,". ", F23,". ", G23,". ", H23) -> Общий расчет. Ци Мень. Анализ Дворца. Комбинации. Нет. Нет | C23: =IFERROR(VLOOKUP(I23,lvl_1[],2,FALSE),"Нет") -> Общий расчет | D23: =IFERROR(VLOOKUP(Rule!J23,lvl_2[],2,FALSE),"Нет") -> Ци Мень | E23: =IFERROR(VLOOKUP(Rule!K23,lvl_3[],2,FALSE),"Нет") -> Анализ Дворца | F23: =IFERROR(INDEX(lvl_4[],MATCH(L23,lvl_4[ID],0),MATCH(TEXT(K23,"##0"),lvl_4[#Headers],0)),"Нет") -> Комбинации | G23: =IFERROR(INDEX(lvl_5[],MATCH(M23,lvl_5[ID],0),MATCH(_xlfn.CONCAT(TEXT(K23,"##0"),"_",TEXT(L23,"##0")),lvl_5[#Headers],0)),"Нет") -> Нет | H23: =IFERROR(INDEX(lvl_6[],MATCH(N23,lvl_6[ID],0),MATCH(_xlfn.CONCAT(K23,"_",L23,"_",M23),lvl_6[#Headers],0)),"Нет") -> Нет | I23: 1 | J23: 2 | K23: 2 | L23: 2 | M23: 0 | N23: 0 | O23: =COUNTIF($P$2:P23,P23) -> 20 | P23: =_xlfn.CONCAT(I23, J23, K23, IF(LEN(L23)=1,_xlfn.CONCAT(0,L23),L23), IF(LEN(M23)=1,_xlfn.CONCAT(0,M23),M23), IF(LEN(N23)=1,_xlfn.CONCAT(0,N23),N23)) -> 122020000 | Q23: =_xlfn.CONCAT(I23, J23, K23, IF(LEN(L23)=1,_xlfn.CONCAT(0,L23),L23), IF(LEN(M23)=1,_xlfn.CONCAT(0,M23),M23), IF(LEN(N23)=1,_xlfn.CONCAT(0,N23),N23), IF(LEN(O23)=1,_xlfn.CONCAT("000",O23),IF(LEN(O23)=2,_xlfn.CONCAT("00",O23),IF(LEN(O23)=3,_xlfn.CONCAT(0,O23),O23)))) -> 1220200000020 | R23: 9 Дунь. Небесный Дунь (Тянь Дунь). Помощь неба | S23: Расцвет во всех делах. Можно подавать прошение, торговать, добиваться повышения. прятать следы, вступать в брак | AY23: 丙 | BA23: 丁 | BB23: 生 | BG23: 1 | BJ23: 1
A24: 1 | B24: =_xlfn.CONCAT(C24,". ", D24,". ", E24,". ", F24,". ", G24,". ", H24) -> Общий расчет. Ци Мень. Анализ Дворца. Комбинации. Нет. Нет | C24: =IFERROR(VLOOKUP(I24,lvl_1[],2,FALSE),"Нет") -> Общий расчет | D24: =IFERROR(VLOOKUP(Rule!J24,lvl_2[],2,FALSE),"Нет") -> Ци Мень | E24: =IFERROR(VLOOKUP(Rule!K24,lvl_3[],2,FALSE),"Нет") -> Анализ Дворца | F24: =IFERROR(INDEX(lvl_4[],MATCH(L24,lvl_4[ID],0),MATCH(TEXT(K24,"##0"),lvl_4[#Headers],0)),"Нет") -> Комбинации | G24: =IFERROR(INDEX(lvl_5[],MATCH(M24,lvl_5[ID],0),MATCH(_xlfn.CONCAT(TEXT(K24,"##0"),"_",TEXT(L24,"##0")),lvl_5[#Headers],0)),"Нет") -> Нет | H24: =IFERROR(INDEX(lvl_6[],MATCH(N24,lvl_6[ID],0),MATCH(_xlfn.CONCAT(K24,"_",L24,"_",M24),lvl_6[#Headers],0)),"Нет") -> Нет | I24: 1 | J24: 2 | K24: 2 | L24: 2 | M24: 0 | N24: 0 | O24: =COUNTIF($P$2:P24,P24) -> 21 | P24: =_xlfn.CONCAT(I24, J24, K24, IF(LEN(L24)=1,_xlfn.CONCAT(0,L24),L24), IF(LEN(M24)=1,_xlfn.CONCAT(0,M24),M24), IF(LEN(N24)=1,_xlfn.CONCAT(0,N24),N24)) -> 122020000 | Q24: =_xlfn.CONCAT(I24, J24, K24, IF(LEN(L24)=1,_xlfn.CONCAT(0,L24),L24), IF(LEN(M24)=1,_xlfn.CONCAT(0,M24),M24), IF(LEN(N24)=1,_xlfn.CONCAT(0,N24),N24), IF(LEN(O24)=1,_xlfn.CONCAT("000",O24),IF(LEN(O24)=2,_xlfn.CONCAT("00",O24),IF(LEN(O24)=3,_xlfn.CONCAT(0,O24),O24)))) -> 1220200000021 | R24: 9 Дунь. Земная структура (Ди Дунь – Di Dun) | S24: Можно легко получить одобрение планов. Можно вести мирные переговоры, подавать прошения, вступать в брак, обороняться | AY24: 乙 | BA24: 己 | BB24: 開 | BG24: 1 | BJ24: 1
A25: 1 | B25: =_xlfn.CONCAT(C25,". ", D25,". ", E25,". ", F25,". ", G25,". ", H25) -> Общий расчет. Ци Мень. Анализ Дворца. Комбинации. Нет. Нет | C25: =IFERROR(VLOOKUP(I25,lvl_1[],2,FALSE),"Нет") -> Общий расчет | D25: =IFERROR(VLOOKUP(Rule!J25,lvl_2[],2,FALSE),"Нет") -> Ци Мень | E25: =IFERROR(VLOOKUP(Rule!K25,lvl_3[],2,FALSE),"Нет") -> Анализ Дворца | F25: =IFERROR(INDEX(lvl_4[],MATCH(L25,lvl_4[ID],0),MATCH(TEXT(K25,"##0"),lvl_4[#Headers],0)),"Нет") -> Комбинации | G25: =IFERROR(INDEX(lvl_5[],MATCH(M25,lvl_5[ID],0),MATCH(_xlfn.CONCAT(TEXT(K25,"##0"),"_",TEXT(L25,"##0")),lvl_5[#Headers],0)),"Нет") -> Нет | H25: =IFERROR(INDEX(lvl_6[],MATCH(N25,lvl_6[ID],0),MATCH(_xlfn.CONCAT(K25,"_",L25,"_",M25),lvl_6[#Headers],0)),"Нет") -> Нет | I25: 1 | J25: 2 | K25: 2 | L25: 2 | M25: 0 | N25: 0 | O25: =COUNTIF($P$2:P25,P25) -> 22 | P25: =_xlfn.CONCAT(I25, J25, K25, IF(LEN(L25)=1,_xlfn.CONCAT(0,L25),L25), IF(LEN(M25)=1,_xlfn.CONCAT(0,M25),M25), IF(LEN(N25)=1,_xlfn.CONCAT(0,N25),N25)) -> 122020000 | Q25: =_xlfn.CONCAT(I25, J25, K25, IF(LEN(L25)=1,_xlfn.CONCAT(0,L25),L25), IF(LEN(M25)=1,_xlfn.CONCAT(0,M25),M25), IF(LEN(N25)=1,_xlfn.CONCAT(0,N25),N25), IF(LEN(O25)=1,_xlfn.CONCAT("000",O25),IF(LEN(O25)=2,_xlfn.CONCAT("00",O25),IF(LEN(O25)=3,_xlfn.CONCAT(0,O25),O25)))) -> 1220200000022 | R25: 9 Дунь. Струтура привидения Гуй Дунь | S25: Для тайных скрытых, ответных действий и передвижений. Благоприятно располагать войска в засаде, шпионить, следить, распространять слухи, заниматься пропагандой | AY25: 乙 | BB25: 杜 | BF25: 地 | BG25: 1 | BJ25: 1
A26: 1 | B26: =_xlfn.CONCAT(C26,". ", D26,". ", E26,". ", F26,". ", G26,". ", H26) -> Общий расчет. Ци Мень. Анализ Дворца. Комбинации. Нет. Нет | C26: =IFERROR(VLOOKUP(I26,lvl_1[],2,FALSE),"Нет") -> Общий расчет | D26: =IFERROR(VLOOKUP(Rule!J26,lvl_2[],2,FALSE),"Нет") -> Ци Мень | E26: =IFERROR(VLOOKUP(Rule!K26,lvl_3[],2,FALSE),"Нет") -> Анализ Дворца | F26: =IFERROR(INDEX(lvl_4[],MATCH(L26,lvl_4[ID],0),MATCH(TEXT(K26,"##0"),lvl_4[#Headers],0)),"Нет") -> Комбинации | G26: =IFERROR(INDEX(lvl_5[],MATCH(M26,lvl_5[ID],0),MATCH(_xlfn.CONCAT(TEXT(K26,"##0"),"_",TEXT(L26,"##0")),lvl_5[#Headers],0)),"Нет") -> Нет | H26: =IFERROR(INDEX(lvl_6[],MATCH(N26,lvl_6[ID],0),MATCH(_xlfn.CONCAT(K26,"_",L26,"_",M26),lvl_6[#Headers],0)),"Нет") -> Нет | I26: 1 | J26: 2 | K26: 2 | L26: 2 | M26: 0 | N26: 0 | O26: =COUNTIF($P$2:P26,P26) -> 23 | P26: =_xlfn.CONCAT(I26, J26, K26, IF(LEN(L26)=1,_xlfn.CONCAT(0,L26),L26), IF(LEN(M26)=1,_xlfn.CONCAT(0,M26),M26), IF(LEN(N26)=1,_xlfn.CONCAT(0,N26),N26)) -> 122020000 | Q26: =_xlfn.CONCAT(I26, J26, K26, IF(LEN(L26)=1,_xlfn.CONCAT(0,L26),L26), IF(LEN(M26)=1,_xlfn.CONCAT(0,M26),M26), IF(LEN(N26)=1,_xlfn.CONCAT(0,N26),N26), IF(LEN(O26)=1,_xlfn.CONCAT("000",O26),IF(LEN(O26)=2,_xlfn.CONCAT("00",O26),IF(LEN(O26)=3,_xlfn.CONCAT(0,O26),O26)))) -> 1220200000023 | R26: 9 Дунь. Структура тигра Ху Дунь | S26: Хорошо для контроля бунтов и мятежей. Можно запугивать противника, чтобы он сдался. Располагать засады. Хорошо для творчества, созидания, можно получить деньги для бизнеса. Возможность счастливых событий | AW26: 8 | AY26: 乙 | BA26: 辛 | BB26: 生 | BG26: 0.5 | BJ26: 1
A27: 1 | B27: =_xlfn.CONCAT(C27,". ", D27,". ", E27,". ", F27,". ", G27,". ", H27) -> Общий расчет. Ци Мень. Анализ Дворца. Комбинации. Нет. Нет | C27: =IFERROR(VLOOKUP(I27,lvl_1[],2,FALSE),"Нет") -> Общий расчет | D27: =IFERROR(VLOOKUP(Rule!J27,lvl_2[],2,FALSE),"Нет") -> Ци Мень | E27: =IFERROR(VLOOKUP(Rule!K27,lvl_3[],2,FALSE),"Нет") -> Анализ Дворца | F27: =IFERROR(INDEX(lvl_4[],MATCH(L27,lvl_4[ID],0),MATCH(TEXT(K27,"##0"),lvl_4[#Headers],0)),"Нет") -> Комбинации | G27: =IFERROR(INDEX(lvl_5[],MATCH(M27,lvl_5[ID],0),MATCH(_xlfn.CONCAT(TEXT(K27,"##0"),"_",TEXT(L27,"##0")),lvl_5[#Headers],0)),"Нет") -> Нет | H27: =IFERROR(INDEX(lvl_6[],MATCH(N27,lvl_6[ID],0),MATCH(_xlfn.CONCAT(K27,"_",L27,"_",M27),lvl_6[#Headers],0)),"Нет") -> Нет | I27: 1 | J27: 2 | K27: 2 | L27: 2 | M27: 0 | N27: 0 | O27: =COUNTIF($P$2:P27,P27) -> 24 | P27: =_xlfn.CONCAT(I27, J27, K27, IF(LEN(L27)=1,_xlfn.CONCAT(0,L27),L27), IF(LEN(M27)=1,_xlfn.CONCAT(0,M27),M27), IF(LEN(N27)=1,_xlfn.CONCAT(0,N27),N27)) -> 122020000 | Q27: =_xlfn.CONCAT(I27, J27, K27, IF(LEN(L27)=1,_xlfn.CONCAT(0,L27),L27), IF(LEN(M27)=1,_xlfn.CONCAT(0,M27),M27), IF(LEN(N27)=1,_xlfn.CONCAT(0,N27),N27), IF(LEN(O27)=1,_xlfn.CONCAT("000",O27),IF(LEN(O27)=2,_xlfn.CONCAT("00",O27),IF(LEN(O27)=3,_xlfn.CONCAT(0,O27),O27)))) -> 1220200000024 | R27: 9 Дунь. Структура ветра. Фэн Дунь – Feng Dun | S27: Хорошо для распространения информации, рекламы, презентаций, продвижения, собраний, путешествий и подготовки к экзаменам | AW27: 4 | AY27: 乙 | BB27: 生 | BG27: 1 | BJ27: 1
A28: 1 | B28: =_xlfn.CONCAT(C28,". ", D28,". ", E28,". ", F28,". ", G28,". ", H28) -> Общий расчет. Ци Мень. Анализ Дворца. Комбинации. Нет. Нет | C28: =IFERROR(VLOOKUP(I28,lvl_1[],2,FALSE),"Нет") -> Общий расчет | D28: =IFERROR(VLOOKUP(Rule!J28,lvl_2[],2,FALSE),"Нет") -> Ци Мень | E28: =IFERROR(VLOOKUP(Rule!K28,lvl_3[],2,FALSE),"Нет") -> Анализ Дворца | F28: =IFERROR(INDEX(lvl_4[],MATCH(L28,lvl_4[ID],0),MATCH(TEXT(K28,"##0"),lvl_4[#Headers],0)),"Нет") -> Комбинации | G28: =IFERROR(INDEX(lvl_5[],MATCH(M28,lvl_5[ID],0),MATCH(_xlfn.CONCAT(TEXT(K28,"##0"),"_",TEXT(L28,"##0")),lvl_5[#Headers],0)),"Нет") -> Нет | H28: =IFERROR(INDEX(lvl_6[],MATCH(N28,lvl_6[ID],0),MATCH(_xlfn.CONCAT(K28,"_",L28,"_",M28),lvl_6[#Headers],0)),"Нет") -> Нет | I28: 1 | J28: 2 | K28: 2 | L28: 2 | M28: 0 | N28: 0 | O28: =COUNTIF($P$2:P28,P28) -> 25 | P28: =_xlfn.CONCAT(I28, J28, K28, IF(LEN(L28)=1,_xlfn.CONCAT(0,L28),L28), IF(LEN(M28)=1,_xlfn.CONCAT(0,M28),M28), IF(LEN(N28)=1,_xlfn.CONCAT(0,N28),N28)) -> 122020000 | Q28: =_xlfn.CONCAT(I28, J28, K28, IF(LEN(L28)=1,_xlfn.CONCAT(0,L28),L28), IF(LEN(M28)=1,_xlfn.CONCAT(0,M28),M28), IF(LEN(N28)=1,_xlfn.CONCAT(0,N28),N28), IF(LEN(O28)=1,_xlfn.CONCAT("000",O28),IF(LEN(O28)=2,_xlfn.CONCAT("00",O28),IF(LEN(O28)=3,_xlfn.CONCAT(0,O28),O28)))) -> 1220200000025 | R28: 9 Дунь. Структура ветра. Фэн Дунь – Feng Dun | S28: Хорошо для распространения информации, рекламы, презентаций, продвижения, собраний, путешествий и подготовки к экзаменам | AW28: 4 | AY28: 乙 | BB28: 開 | BG28: 1 | BJ28: 1
A29: 1 | B29: =_xlfn.CONCAT(C29,". ", D29,". ", E29,". ", F29,". ", G29,". ", H29) -> Общий расчет. Ци Мень. Анализ Дворца. Комбинации. Нет. Нет | C29: =IFERROR(VLOOKUP(I29,lvl_1[],2,FALSE),"Нет") -> Общий расчет | D29: =IFERROR(VLOOKUP(Rule!J29,lvl_2[],2,FALSE),"Нет") -> Ци Мень | E29: =IFERROR(VLOOKUP(Rule!K29,lvl_3[],2,FALSE),"Нет") -> Анализ Дворца | F29: =IFERROR(INDEX(lvl_4[],MATCH(L29,lvl_4[ID],0),MATCH(TEXT(K29,"##0"),lvl_4[#Headers],0)),"Нет") -> Комбинации | G29: =IFERROR(INDEX(lvl_5[],MATCH(M29,lvl_5[ID],0),MATCH(_xlfn.CONCAT(TEXT(K29,"##0"),"_",TEXT(L29,"##0")),lvl_5[#Headers],0)),"Нет") -> Нет | H29: =IFERROR(INDEX(lvl_6[],MATCH(N29,lvl_6[ID],0),MATCH(_xlfn.CONCAT(K29,"_",L29,"_",M29),lvl_6[#Headers],0)),"Нет") -> Нет | I29: 1 | J29: 2 | K29: 2 | L29: 2 | M29: 0 | N29: 0 | O29: =COUNTIF($P$2:P29,P29) -> 26 | P29: =_xlfn.CONCAT(I29, J29, K29, IF(LEN(L29)=1,_xlfn.CONCAT(0,L29),L29), IF(LEN(M29)=1,_xlfn.CONCAT(0,M29),M29), IF(LEN(N29)=1,_xlfn.CONCAT(0,N29),N29)) -> 122020000 | Q29: =_xlfn.CONCAT(I29, J29, K29, IF(LEN(L29)=1,_xlfn.CONCAT(0,L29),L29), IF(LEN(M29)=1,_xlfn.CONCAT(0,M29),M29), IF(LEN(N29)=1,_xlfn.CONCAT(0,N29),N29), IF(LEN(O29)=1,_xlfn.CONCAT("000",O29),IF(LEN(O29)=2,_xlfn.CONCAT("00",O29),IF(LEN(O29)=3,_xlfn.CONCAT(0,O29),O29)))) -> 1220200000026 | R29: 9 Дунь. Структура ветра. Фэн Дунь – Feng Dun | S29: Хорошо для распространения информации, рекламы, презентаций, продвижения, собраний, путешествий и подготовки к экзаменам | AW29: 4 | AY29: 乙 | BB29: 休 | BG29: 1 | BJ29: 1
